Qubicle Exchange Format
Version 0.2
www.minddesk.com
27 32 29
1626
0.039216 0.011765 0.007843
0.047059 0.027451 0.043137
0.054902 0.035294 0.023529
0.054902 0.039216 0.101961
0.058824 0.050980 0.094118
0.058824 0.050980 0.109804
0.062745 0.047059 0.070588
0.062745 0.050980 0.094118
0.062745 0.054902 0.086275
0.062745 0.054902 0.121569
0.062745 0.062745 0.070588
0.066667 0.054902 0.117647
0.066667 0.058824 0.101961
0.066667 0.058824 0.109804
0.066667 0.058824 0.113725
0.066667 0.062745 0.117647
0.066667 0.066667 0.117647
0.066667 0.074510 0.121569
0.066667 0.074510 0.125490
0.070588 0.054902 0.109804
0.070588 0.058824 0.101961
0.070588 0.062745 0.105882
0.070588 0.062745 0.109804
0.070588 0.062745 0.113725
0.070588 0.066667 0.086275
0.070588 0.066667 0.098039
0.070588 0.066667 0.101961
0.070588 0.066667 0.117647
0.070588 0.078431 0.129412
0.074510 0.058824 0.094118
0.074510 0.058824 0.117647
0.074510 0.062745 0.090196
0.074510 0.062745 0.101961
0.074510 0.062745 0.105882
0.074510 0.066667 0.078431
0.074510 0.066667 0.105882
0.074510 0.066667 0.109804
0.074510 0.066667 0.113725
0.074510 0.066667 0.117647
0.074510 0.066667 0.121569
0.074510 0.070588 0.090196
0.074510 0.070588 0.101961
0.074510 0.070588 0.133333
0.078431 0.062745 0.117647
0.078431 0.066667 0.141176
0.078431 0.070588 0.113725
0.078431 0.070588 0.117647
0.078431 0.070588 0.121569
0.078431 0.070588 0.125490
0.078431 0.070588 0.152941
0.078431 0.074510 0.101961
0.078431 0.074510 0.125490
0.078431 0.074510 0.137255
0.078431 0.074510 0.145098
0.078431 0.082353 0.152941
0.082353 0.050980 0.039216
0.082353 0.062745 0.082353
0.082353 0.062745 0.086275
0.082353 0.062745 0.094118
0.082353 0.066667 0.105882
0.082353 0.066667 0.117647
0.082353 0.070588 0.098039
0.082353 0.070588 0.137255
0.082353 0.070588 0.141176
0.082353 0.074510 0.109804
0.082353 0.074510 0.117647
0.082353 0.074510 0.121569
0.082353 0.074510 0.125490
0.082353 0.074510 0.129412
0.082353 0.078431 0.101961
0.082353 0.078431 0.109804
0.082353 0.078431 0.117647
0.082353 0.078431 0.133333
0.082353 0.082353 0.113725
0.082353 0.090196 0.149020
0.086275 0.062745 0.101961
0.086275 0.066667 0.082353
0.086275 0.070588 0.125490
0.086275 0.074510 0.105882
0.086275 0.074510 0.109804
0.086275 0.074510 0.121569
0.086275 0.074510 0.149020
0.086275 0.078431 0.121569
0.086275 0.078431 0.125490
0.086275 0.078431 0.129412
0.086275 0.078431 0.133333
0.086275 0.082353 0.145098
0.090196 0.066667 0.090196
0.090196 0.074510 0.133333
0.090196 0.078431 0.090196
0.090196 0.078431 0.098039
0.090196 0.078431 0.109804
0.090196 0.078431 0.113725
0.090196 0.078431 0.152941
0.090196 0.082353 0.105882
0.090196 0.082353 0.125490
0.090196 0.082353 0.129412
0.090196 0.082353 0.133333
0.090196 0.082353 0.137255
0.090196 0.082353 0.149020
0.090196 0.082353 0.168627
0.090196 0.086275 0.121569
0.090196 0.086275 0.137255
0.090196 0.086275 0.160784
0.090196 0.090196 0.113725
0.090196 0.090196 0.129412
0.090196 0.090196 0.133333
0.094118 0.035294 0.054902
0.094118 0.062745 0.105882
0.094118 0.070588 0.082353
0.094118 0.070588 0.113725
0.094118 0.070588 0.145098
0.094118 0.074510 0.098039
0.094118 0.078431 0.129412
0.094118 0.078431 0.137255
0.094118 0.078431 0.145098
0.094118 0.082353 0.117647
0.094118 0.082353 0.129412
0.094118 0.082353 0.156863
0.094118 0.086275 0.101961
0.094118 0.086275 0.129412
0.094118 0.086275 0.141176
0.094118 0.086275 0.168627
0.094118 0.090196 0.105882
0.094118 0.090196 0.121569
0.094118 0.090196 0.145098
0.094118 0.090196 0.149020
0.094118 0.094118 0.141176
0.094118 0.094118 0.160784
0.098039 0.066667 0.094118
0.098039 0.074510 0.113725
0.098039 0.078431 0.105882
0.098039 0.086275 0.121569
0.098039 0.086275 0.133333
0.098039 0.086275 0.141176
0.098039 0.086275 0.152941
0.098039 0.086275 0.164706
0.098039 0.090196 0.117647
0.098039 0.090196 0.125490
0.098039 0.090196 0.141176
0.098039 0.094118 0.149020
0.101961 0.047059 0.035294
0.101961 0.078431 0.090196
0.101961 0.078431 0.125490
0.101961 0.078431 0.129412
0.101961 0.082353 0.101961
0.101961 0.086275 0.113725
0.101961 0.086275 0.125490
0.101961 0.086275 0.141176
0.101961 0.086275 0.145098
0.101961 0.090196 0.125490
0.101961 0.090196 0.149020
0.101961 0.090196 0.160784
0.101961 0.090196 0.168627
0.101961 0.094118 0.113725
0.101961 0.094118 0.129412
0.101961 0.094118 0.137255
0.101961 0.094118 0.145098
0.101961 0.094118 0.149020
0.101961 0.094118 0.152941
0.101961 0.094118 0.160784
0.101961 0.094118 0.188235
0.101961 0.098039 0.152941
0.101961 0.098039 0.160784
0.101961 0.098039 0.168627
0.101961 0.101961 0.149020
0.101961 0.109804 0.168627
0.105882 0.074510 0.141176
0.105882 0.086275 0.101961
0.105882 0.086275 0.109804
0.105882 0.090196 0.145098
0.105882 0.090196 0.160784
0.105882 0.094118 0.117647
0.105882 0.094118 0.121569
0.105882 0.094118 0.129412
0.105882 0.094118 0.137255
0.105882 0.094118 0.160784
0.105882 0.094118 0.188235
0.105882 0.098039 0.141176
0.105882 0.098039 0.149020
0.105882 0.098039 0.176471
0.105882 0.101961 0.129412
0.105882 0.101961 0.145098
0.105882 0.101961 0.152941
0.105882 0.101961 0.164706
0.109804 0.070588 0.074510
0.109804 0.074510 0.105882
0.109804 0.078431 0.109804
0.109804 0.086275 0.133333
0.109804 0.086275 0.141176
0.109804 0.086275 0.145098
0.109804 0.090196 0.137255
0.109804 0.094118 0.125490
0.109804 0.094118 0.129412
0.109804 0.094118 0.149020
0.109804 0.094118 0.184314
0.109804 0.098039 0.133333
0.109804 0.098039 0.141176
0.109804 0.101961 0.152941
0.109804 0.105882 0.129412
0.109804 0.105882 0.156863
0.109804 0.109804 0.160784
0.109804 0.109804 0.184314
0.113725 0.066667 0.047059
0.113725 0.066667 0.074510
0.113725 0.070588 0.109804
0.113725 0.082353 0.101961
0.113725 0.086275 0.090196
0.113725 0.086275 0.117647
0.113725 0.090196 0.121569
0.113725 0.090196 0.129412
0.113725 0.094118 0.121569
0.113725 0.098039 0.101961
0.113725 0.098039 0.133333
0.113725 0.098039 0.156863
0.113725 0.101961 0.145098
0.113725 0.105882 0.129412
0.113725 0.105882 0.133333
0.113725 0.105882 0.141176
0.113725 0.105882 0.152941
0.113725 0.105882 0.156863
0.113725 0.109804 0.141176
0.113725 0.109804 0.176471
0.113725 0.113725 0.176471
0.113725 0.121569 0.172549
0.117647 0.074510 0.090196
0.117647 0.078431 0.082353
0.117647 0.094118 0.137255
0.117647 0.098039 0.121569
0.117647 0.098039 0.125490
0.117647 0.098039 0.176471
0.117647 0.101961 0.105882
0.117647 0.101961 0.129412
0.117647 0.101961 0.156863
0.117647 0.101961 0.160784
0.117647 0.101961 0.172549
0.117647 0.105882 0.137255
0.117647 0.105882 0.172549
0.117647 0.113725 0.152941
0.117647 0.125490 0.149020
0.117647 0.125490 0.160784
0.121569 0.082353 0.086275
0.121569 0.086275 0.129412
0.121569 0.094118 0.160784
0.121569 0.098039 0.129412
0.121569 0.101961 0.149020
0.121569 0.105882 0.156863
0.121569 0.105882 0.164706
0.121569 0.109804 0.168627
0.121569 0.113725 0.164706
0.121569 0.113725 0.168627
0.121569 0.113725 0.196078
0.121569 0.117647 0.149020
0.125490 0.078431 0.078431
0.125490 0.086275 0.090196
0.125490 0.094118 0.145098
0.125490 0.094118 0.180392
0.125490 0.101961 0.117647
0.125490 0.109804 0.164706
0.125490 0.109804 0.168627
0.125490 0.113725 0.180392
0.125490 0.113725 0.196078
0.125490 0.117647 0.121569
0.125490 0.125490 0.184314
0.129412 0.086275 0.105882
0.129412 0.086275 0.117647
0.129412 0.094118 0.113725
0.129412 0.101961 0.152941
0.129412 0.105882 0.113725
0.129412 0.109804 0.133333
0.129412 0.113725 0.176471
0.129412 0.117647 0.149020
0.129412 0.117647 0.168627
0.129412 0.117647 0.176471
0.129412 0.121569 0.141176
0.129412 0.149020 0.227451
0.133333 0.058824 0.082353
0.133333 0.094118 0.156863
0.133333 0.098039 0.188235
0.133333 0.101961 0.101961
0.133333 0.101961 0.121569
0.133333 0.105882 0.129412
0.133333 0.105882 0.192157
0.133333 0.113725 0.141176
0.133333 0.117647 0.160784
0.133333 0.117647 0.172549
0.133333 0.117647 0.176471
0.133333 0.121569 0.180392
0.133333 0.125490 0.180392
0.133333 0.125490 0.188235
0.133333 0.125490 0.207843
0.133333 0.129412 0.188235
0.133333 0.149020 0.239216
0.137255 0.086275 0.113725
0.137255 0.101961 0.082353
0.137255 0.101961 0.149020
0.137255 0.109804 0.172549
0.137255 0.113725 0.129412
0.137255 0.117647 0.180392
0.137255 0.121569 0.180392
0.137255 0.121569 0.196078
0.137255 0.121569 0.200000
0.137255 0.125490 0.149020
0.137255 0.125490 0.164706
0.137255 0.129412 0.184314
0.137255 0.133333 0.176471
0.141176 0.101961 0.078431
0.141176 0.105882 0.125490
0.141176 0.109804 0.121569
0.141176 0.113725 0.125490
0.141176 0.113725 0.160784
0.141176 0.113725 0.176471
0.141176 0.121569 0.125490
0.141176 0.125490 0.152941
0.141176 0.129412 0.192157
0.141176 0.133333 0.184314
0.141176 0.133333 0.188235
0.145098 0.086275 0.133333
0.145098 0.090196 0.078431
0.145098 0.101961 0.125490
0.145098 0.105882 0.109804
0.145098 0.105882 0.156863
0.145098 0.109804 0.105882
0.145098 0.109804 0.113725
0.145098 0.109804 0.117647
0.145098 0.113725 0.164706
0.145098 0.117647 0.149020
0.145098 0.129412 0.180392
0.145098 0.129412 0.192157
0.145098 0.133333 0.149020
0.145098 0.133333 0.180392
0.145098 0.133333 0.219608
0.145098 0.176471 0.254902
0.149020 0.113725 0.141176
0.149020 0.113725 0.152941
0.149020 0.121569 0.192157
0.149020 0.133333 0.149020
0.149020 0.133333 0.203922
0.149020 0.141176 0.188235
0.149020 0.145098 0.227451
0.152941 0.105882 0.145098
0.152941 0.109804 0.113725
0.152941 0.109804 0.141176
0.152941 0.113725 0.113725
0.152941 0.113725 0.141176
0.152941 0.113725 0.145098
0.152941 0.117647 0.168627
0.152941 0.121569 0.188235
0.152941 0.125490 0.152941
0.152941 0.129412 0.156863
0.152941 0.133333 0.145098
0.152941 0.137255 0.180392
0.152941 0.137255 0.192157
0.152941 0.141176 0.184314
0.156863 0.086275 0.090196
0.156863 0.109804 0.109804
0.156863 0.129412 0.152941
0.156863 0.133333 0.188235
0.156863 0.141176 0.203922
0.156863 0.145098 0.168627
0.156863 0.149020 0.196078
0.160784 0.101961 0.145098
0.160784 0.117647 0.133333
0.160784 0.121569 0.129412
0.160784 0.129412 0.125490
0.160784 0.129412 0.176471
0.160784 0.133333 0.152941
0.160784 0.133333 0.196078
0.160784 0.137255 0.160784
0.160784 0.137255 0.164706
0.160784 0.141176 0.168627
0.160784 0.141176 0.188235
0.160784 0.141176 0.196078
0.160784 0.152941 0.176471
0.164706 0.094118 0.141176
0.164706 0.121569 0.101961
0.164706 0.121569 0.117647
0.164706 0.145098 0.203922
0.164706 0.156863 0.192157
0.168627 0.121569 0.090196
0.168627 0.121569 0.164706
0.168627 0.125490 0.156863
0.168627 0.125490 0.160784
0.168627 0.137255 0.133333
0.168627 0.137255 0.180392
0.168627 0.137255 0.192157
0.168627 0.145098 0.129412
0.168627 0.152941 0.149020
0.168627 0.152941 0.211765
0.168627 0.156863 0.223529
0.168627 0.160784 0.211765
0.168627 0.164706 0.235294
0.168627 0.172549 0.254902
0.172549 0.125490 0.192157
0.172549 0.129412 0.117647
0.172549 0.133333 0.164706
0.172549 0.137255 0.156863
0.172549 0.137255 0.176471
0.172549 0.141176 0.184314
0.172549 0.141176 0.192157
0.172549 0.145098 0.203922
0.172549 0.149020 0.156863
0.172549 0.149020 0.196078
0.176471 0.121569 0.121569
0.176471 0.133333 0.113725
0.176471 0.137255 0.121569
0.176471 0.137255 0.141176
0.176471 0.149020 0.172549
0.176471 0.152941 0.160784
0.176471 0.156863 0.152941
0.176471 0.156863 0.211765
0.176471 0.227451 0.400000
0.180392 0.125490 0.113725
0.180392 0.129412 0.172549
0.180392 0.133333 0.109804
0.180392 0.133333 0.176471
0.180392 0.137255 0.125490
0.180392 0.137255 0.129412
0.180392 0.145098 0.164706
0.180392 0.149020 0.188235
0.180392 0.156863 0.196078
0.180392 0.160784 0.176471
0.180392 0.176471 0.211765
0.184314 0.133333 0.176471
0.184314 0.137255 0.145098
0.184314 0.137255 0.172549
0.184314 0.137255 0.176471
0.184314 0.137255 0.192157
0.184314 0.141176 0.133333
0.184314 0.141176 0.156863
0.184314 0.145098 0.141176
0.184314 0.152941 0.145098
0.184314 0.156863 0.196078
0.188235 0.137255 0.105882
0.188235 0.141176 0.113725
0.188235 0.141176 0.152941
0.188235 0.145098 0.133333
0.188235 0.149020 0.192157
0.192157 0.070588 0.090196
0.192157 0.152941 0.172549
0.192157 0.156863 0.203922
0.192157 0.164706 0.196078
0.192157 0.164706 0.231373
0.192157 0.172549 0.203922
0.192157 0.172549 0.239216
0.192157 0.176471 0.243137
0.192157 0.184314 0.223529
0.196078 0.125490 0.121569
0.196078 0.141176 0.133333
0.196078 0.149020 0.137255
0.196078 0.149020 0.172549
0.196078 0.149020 0.192157
0.196078 0.152941 0.184314
0.196078 0.156863 0.188235
0.200000 0.145098 0.109804
0.200000 0.149020 0.133333
0.200000 0.156863 0.145098
0.200000 0.180392 0.227451
0.203922 0.137255 0.133333
0.203922 0.160784 0.192157
0.203922 0.164706 0.207843
0.203922 0.168627 0.180392
0.203922 0.184314 0.235294
0.207843 0.156863 0.125490
0.207843 0.168627 0.172549
0.207843 0.184314 0.239216
0.207843 0.200000 0.254902
0.207843 0.200000 0.258824
0.211765 0.156863 0.188235
0.211765 0.164706 0.207843
0.211765 0.168627 0.172549
0.211765 0.176471 0.211765
0.211765 0.180392 0.200000
0.211765 0.184314 0.215686
0.215686 0.156863 0.207843
0.215686 0.160784 0.129412
0.215686 0.160784 0.133333
0.215686 0.203922 0.262745
0.219608 0.145098 0.133333
0.219608 0.164706 0.129412
0.219608 0.180392 0.247059
0.219608 0.192157 0.211765
0.219608 0.192157 0.254902
0.219608 0.203922 0.262745
0.219608 0.211765 0.262745
0.223529 0.184314 0.176471
0.223529 0.188235 0.266667
0.227451 0.172549 0.141176
0.227451 0.196078 0.227451
0.231373 0.172549 0.125490
0.231373 0.176471 0.137255
0.231373 0.176471 0.141176
0.231373 0.180392 0.145098
0.231373 0.180392 0.152941
0.231373 0.184314 0.223529
0.231373 0.192157 0.235294
0.231373 0.207843 0.266667
0.235294 0.168627 0.192157
0.235294 0.180392 0.145098
0.235294 0.180392 0.207843
0.235294 0.207843 0.278431
0.239216 0.172549 0.219608
0.239216 0.184314 0.145098
0.239216 0.184314 0.149020
0.239216 0.192157 0.207843
0.239216 0.192157 0.231373
0.239216 0.211765 0.227451
0.239216 0.215686 0.239216
0.243137 0.168627 0.121569
0.243137 0.188235 0.149020
0.243137 0.203922 0.192157
0.243137 0.207843 0.227451
0.243137 0.207843 0.294118
0.243137 0.211765 0.188235
0.243137 0.215686 0.258824
0.243137 0.250980 0.290196
0.247059 0.192157 0.149020
0.247059 0.192157 0.152941
0.247059 0.200000 0.188235
0.247059 0.211765 0.294118
0.250980 0.200000 0.235294
0.250980 0.223529 0.196078
0.250980 0.227451 0.250980
0.254902 0.192157 0.137255
0.254902 0.192157 0.149020
0.254902 0.219608 0.231373
0.254902 0.266667 0.337255
0.258824 0.200000 0.152941
0.258824 0.203922 0.219608
0.258824 0.243137 0.309804
0.262745 0.203922 0.152941
0.262745 0.215686 0.223529
0.262745 0.235294 0.286275
0.266667 0.192157 0.172549
0.266667 0.203922 0.215686
0.266667 0.207843 0.156863
0.270588 0.203922 0.160784
0.270588 0.203922 0.164706
0.270588 0.215686 0.266667
0.270588 0.239216 0.243137
0.274510 0.203922 0.160784
0.274510 0.223529 0.180392
0.274510 0.227451 0.258824
0.274510 0.313726 0.392157
0.278431 0.184314 0.164706
0.278431 0.211765 0.156863
0.278431 0.211765 0.160784
0.278431 0.215686 0.160784
0.278431 0.215686 0.164706
0.278431 0.250980 0.282353
0.282353 0.196078 0.149020
0.282353 0.219608 0.168627
0.282353 0.227451 0.219608
0.286275 0.223529 0.160784
0.286275 0.223529 0.176471
0.290196 0.258824 0.317647
0.294118 0.215686 0.145098
0.294118 0.223529 0.172549
0.294118 0.223529 0.176471
0.294118 0.223529 0.258824
0.294118 0.227451 0.168627
0.294118 0.231373 0.188235
0.294118 0.243137 0.196078
0.294118 0.274510 0.301961
0.298039 0.227451 0.168627
0.298039 0.235294 0.176471
0.298039 0.235294 0.184314
0.301961 0.231373 0.176471
0.301961 0.235294 0.180392
0.301961 0.243137 0.215686
0.301961 0.290196 0.325490
0.305882 0.235294 0.180392
0.305882 0.239216 0.172549
0.305882 0.239216 0.176471
0.305882 0.239216 0.180392
0.305882 0.247059 0.258824
0.305882 0.266667 0.282353
0.309804 0.227451 0.188235
0.309804 0.243137 0.176471
0.309804 0.243137 0.180392
0.309804 0.270588 0.250980
0.309804 0.282353 0.313726
0.313726 0.243137 0.184314
0.313726 0.278431 0.341176
0.317647 0.211765 0.160784
0.317647 0.239216 0.231373
0.317647 0.250980 0.188235
0.317647 0.250980 0.192157
0.317647 0.250980 0.219608
0.321569 0.250980 0.188235
0.321569 0.254902 0.188235
0.321569 0.266667 0.235294
0.321569 0.270588 0.298039
0.321569 0.290196 0.294118
0.325490 0.254902 0.188235
0.325490 0.254902 0.196078
0.325490 0.258824 0.192157
0.325490 0.309804 0.266667
0.329412 0.262745 0.192157
0.329412 0.262745 0.196078
0.333333 0.262745 0.196078
0.333333 0.270588 0.180392
0.333333 0.290196 0.203922
0.337255 0.247059 0.188235
0.337255 0.250980 0.176471
0.337255 0.262745 0.196078
0.337255 0.266667 0.196078
0.337255 0.266667 0.200000
0.337255 0.270588 0.192157
0.337255 0.270588 0.203922
0.337255 0.278431 0.305882
0.341176 0.250980 0.188235
0.341176 0.301961 0.298039
0.341176 0.301961 0.333333
0.345098 0.270588 0.200000
0.345098 0.270588 0.203922
0.345098 0.278431 0.211765
0.349020 0.270588 0.211765
0.349020 0.274510 0.207843
0.352941 0.247059 0.203922
0.352941 0.270588 0.219608
0.352941 0.278431 0.207843
0.352941 0.278431 0.211765
0.352941 0.290196 0.223529
0.352941 0.301961 0.298039
0.352941 0.305882 0.290196
0.356863 0.282353 0.200000
0.356863 0.282353 0.211765
0.356863 0.286275 0.207843
0.356863 0.286275 0.211765
0.356863 0.286275 0.215686
0.356863 0.301961 0.262745
0.360784 0.282353 0.239216
0.360784 0.286275 0.211765
0.360784 0.286275 0.215686
0.360784 0.294118 0.215686
0.360784 0.352941 0.400000
0.364706 0.294118 0.211765
0.364706 0.294118 0.215686
0.368627 0.282353 0.200000
0.368627 0.282353 0.231373
0.368627 0.290196 0.211765
0.368627 0.290196 0.215686
0.368627 0.294118 0.215686
0.368627 0.294118 0.258824
0.368627 0.325490 0.301961
0.368627 0.352941 0.407843
0.372549 0.262745 0.207843
0.372549 0.270588 0.219608
0.372549 0.290196 0.219608
0.372549 0.294118 0.203922
0.372549 0.294118 0.219608
0.372549 0.298039 0.215686
0.372549 0.301961 0.215686
0.372549 0.301961 0.219608
0.372549 0.305882 0.258824
0.376471 0.274510 0.180392
0.376471 0.294118 0.215686
0.376471 0.301961 0.207843
0.376471 0.305882 0.215686
0.376471 0.305882 0.227451
0.380392 0.294118 0.219608
0.380392 0.298039 0.223529
0.380392 0.301961 0.219608
0.380392 0.301961 0.223529
0.380392 0.301961 0.235294
0.380392 0.305882 0.219608
0.380392 0.309804 0.223529
0.384314 0.294118 0.219608
0.384314 0.301961 0.219608
0.384314 0.305882 0.215686
0.384314 0.309804 0.215686
0.384314 0.309804 0.243137
0.384314 0.313726 0.223529
0.384314 0.345098 0.321569
0.388235 0.301961 0.235294
0.388235 0.305882 0.223529
0.388235 0.305882 0.239216
0.388235 0.309804 0.223529
0.388235 0.309804 0.227451
0.388235 0.317647 0.274510
0.388235 0.345098 0.329412
0.392157 0.278431 0.227451
0.392157 0.301961 0.219608
0.392157 0.305882 0.215686
0.392157 0.305882 0.223529
0.392157 0.309804 0.219608
0.392157 0.309804 0.231373
0.392157 0.313726 0.254902
0.396078 0.254902 0.188235
0.396078 0.301961 0.250980
0.396078 0.313726 0.223529
0.396078 0.313726 0.227451
0.396078 0.313726 0.231373
0.396078 0.317647 0.223529
0.396078 0.317647 0.227451
0.396078 0.447059 0.466667
0.400000 0.309804 0.223529
0.400000 0.309804 0.227451
0.400000 0.313726 0.223529
0.400000 0.313726 0.231373
0.400000 0.313726 0.235294
0.400000 0.317647 0.235294
0.400000 0.321569 0.227451
0.400000 0.321569 0.231373
0.400000 0.337255 0.270588
0.400000 0.352941 0.364706
0.403922 0.313726 0.243137
0.403922 0.317647 0.227451
0.403922 0.317647 0.243137
0.403922 0.321569 0.239216
0.403922 0.325490 0.231373
0.403922 0.329412 0.250980
0.407843 0.321569 0.227451
0.407843 0.321569 0.231373
0.407843 0.329412 0.235294
0.407843 0.333333 0.274510
0.411765 0.321569 0.231373
0.411765 0.321569 0.235294
0.411765 0.325490 0.231373
0.411765 0.325490 0.235294
0.411765 0.325490 0.239216
0.411765 0.325490 0.243137
0.411765 0.333333 0.235294
0.411765 0.337255 0.250980
0.415686 0.321569 0.227451
0.415686 0.329412 0.235294
0.415686 0.329412 0.239216
0.415686 0.329412 0.250980
0.415686 0.333333 0.239216
0.415686 0.333333 0.243137
0.415686 0.333333 0.247059
0.415686 0.333333 0.313726
0.415686 0.337255 0.239216
0.415686 0.384314 0.415686
0.415686 0.396078 0.439216
0.419608 0.317647 0.227451
0.419608 0.321569 0.231373
0.419608 0.321569 0.235294
0.419608 0.325490 0.231373
0.419608 0.329412 0.243137
0.419608 0.333333 0.243137
0.419608 0.333333 0.250980
0.419608 0.337255 0.258824
0.419608 0.341176 0.243137
0.419608 0.341176 0.262745
0.423529 0.329412 0.227451
0.423529 0.329412 0.231373
0.423529 0.329412 0.235294
0.423529 0.333333 0.235294
0.423529 0.337255 0.243137
0.423529 0.337255 0.247059
0.423529 0.341176 0.247059
0.423529 0.345098 0.247059
0.427451 0.329412 0.258824
0.427451 0.333333 0.239216
0.427451 0.337255 0.243137
0.427451 0.341176 0.250980
0.431373 0.309804 0.200000
0.431373 0.333333 0.219608
0.431373 0.333333 0.247059
0.431373 0.337255 0.243137
0.431373 0.341176 0.250980
0.431373 0.345098 0.250980
0.431373 0.345098 0.254902
0.431373 0.345098 0.258824
0.431373 0.349020 0.247059
0.431373 0.349020 0.254902
0.431373 0.349020 0.266667
0.431373 0.400000 0.396078
0.435294 0.329412 0.235294
0.435294 0.337255 0.250980
0.435294 0.341176 0.247059
0.435294 0.345098 0.250980
0.435294 0.349020 0.258824
0.435294 0.352941 0.235294
0.435294 0.352941 0.247059
0.439216 0.333333 0.227451
0.439216 0.341176 0.250980
0.439216 0.345098 0.243137
0.439216 0.345098 0.247059
0.439216 0.345098 0.250980
0.439216 0.349020 0.250980
0.439216 0.352941 0.258824
0.439216 0.352941 0.262745
0.439216 0.352941 0.270588
0.439216 0.356863 0.254902
0.439216 0.356863 0.262745
0.439216 0.407843 0.380392
0.443137 0.345098 0.223529
0.443137 0.349020 0.250980
0.443137 0.352941 0.258824
0.443137 0.356863 0.262745
0.443137 0.392157 0.360784
0.443137 0.443137 0.450980
0.447059 0.325490 0.243137
0.447059 0.345098 0.250980
0.447059 0.349020 0.243137
0.447059 0.352941 0.250980
0.447059 0.352941 0.258824
0.447059 0.364706 0.294118
0.450980 0.356863 0.258824
0.450980 0.360784 0.266667
0.450980 0.360784 0.274510
0.454902 0.333333 0.247059
0.454902 0.360784 0.258824
0.454902 0.364706 0.262745
0.454902 0.364706 0.274510
0.454902 0.368627 0.235294
0.454902 0.376471 0.250980
0.458824 0.364706 0.254902
0.458824 0.364706 0.262745
0.458824 0.368627 0.274510
0.458824 0.372549 0.250980
0.458824 0.376471 0.250980
0.458824 0.376471 0.352941
0.462745 0.360784 0.258824
0.462745 0.360784 0.262745
0.462745 0.364706 0.250980
0.462745 0.368627 0.262745
0.462745 0.368627 0.266667
0.462745 0.368627 0.270588
0.462745 0.376471 0.294118
0.462745 0.419608 0.454902
0.466667 0.368627 0.258824
0.466667 0.372549 0.270588
0.466667 0.372549 0.278431
0.466667 0.372549 0.286275
0.466667 0.376471 0.254902
0.466667 0.376471 0.270588
0.466667 0.376471 0.313726
0.466667 0.403922 0.317647
0.466667 0.423529 0.325490
0.466667 0.462745 0.521569
0.470588 0.372549 0.262745
0.470588 0.372549 0.266667
0.470588 0.376471 0.266667
0.470588 0.376471 0.270588
0.470588 0.376471 0.274510
0.470588 0.376471 0.282353
0.470588 0.376471 0.290196
0.470588 0.380392 0.309804
0.474510 0.376471 0.262745
0.474510 0.376471 0.286275
0.474510 0.380392 0.286275
0.474510 0.384314 0.258824
0.474510 0.388235 0.301961
0.474510 0.474510 0.513726
0.478431 0.372549 0.258824
0.478431 0.384314 0.270588
0.478431 0.384314 0.274510
0.478431 0.396078 0.298039
0.482353 0.384314 0.266667
0.482353 0.388235 0.266667
0.482353 0.388235 0.274510
0.482353 0.388235 0.278431
0.482353 0.388235 0.294118
0.482353 0.396078 0.290196
0.482353 0.400000 0.423529
0.482353 0.419608 0.360784
0.486275 0.380392 0.266667
0.486275 0.388235 0.294118
0.486275 0.388235 0.301961
0.486275 0.392157 0.274510
0.486275 0.392157 0.290196
0.486275 0.392157 0.298039
0.486275 0.396078 0.262745
0.486275 0.396078 0.266667
0.486275 0.427451 0.349020
0.486275 0.439216 0.439216
0.486275 0.462745 0.411765
0.490196 0.352941 0.266667
0.490196 0.392157 0.274510
0.490196 0.392157 0.286275
0.490196 0.396078 0.286275
0.490196 0.396078 0.290196
0.490196 0.443137 0.380392
0.490196 0.450980 0.474510
0.490196 0.482353 0.474510
0.490196 0.494118 0.537255
0.494118 0.392157 0.258824
0.494118 0.392157 0.274510
0.494118 0.396078 0.274510
0.494118 0.396078 0.278431
0.494118 0.396078 0.298039
0.494118 0.400000 0.266667
0.494118 0.400000 0.278431
0.494118 0.403922 0.258824
0.494118 0.403922 0.262745
0.494118 0.403922 0.282353
0.494118 0.419608 0.290196
0.494118 0.458824 0.470588
0.498039 0.396078 0.298039
0.498039 0.400000 0.282353
0.498039 0.400000 0.286275
0.498039 0.403922 0.274510
0.498039 0.403922 0.294118
0.498039 0.407843 0.270588
0.501961 0.388235 0.250980
0.501961 0.400000 0.286275
0.501961 0.400000 0.301961
0.501961 0.403922 0.282353
0.501961 0.403922 0.286275
0.501961 0.403922 0.290196
0.501961 0.407843 0.266667
0.501961 0.407843 0.270588
0.501961 0.407843 0.286275
0.501961 0.411765 0.262745
0.501961 0.411765 0.270588
0.501961 0.470588 0.439216
0.501961 0.482353 0.474510
0.505882 0.411765 0.274510
0.505882 0.411765 0.278431
0.505882 0.411765 0.290196
0.505882 0.411765 0.301961
0.505882 0.415686 0.266667
0.505882 0.415686 0.282353
0.505882 0.431373 0.274510
0.505882 0.435294 0.380392
0.505882 0.470588 0.458824
0.509804 0.411765 0.294118
0.509804 0.411765 0.298039
0.509804 0.411765 0.313726
0.509804 0.415686 0.278431
0.509804 0.415686 0.298039
0.509804 0.415686 0.309804
0.509804 0.415686 0.313726
0.509804 0.419608 0.321569
0.509804 0.423529 0.266667
0.509804 0.427451 0.286275
0.509804 0.435294 0.368627
0.509804 0.443137 0.364706
0.509804 0.482353 0.454902
0.509804 0.505882 0.560784
0.513726 0.392157 0.274510
0.513726 0.400000 0.282353
0.513726 0.415686 0.298039
0.513726 0.415686 0.305882
0.513726 0.419608 0.294118
0.513726 0.427451 0.282353
0.513726 0.427451 0.337255
0.513726 0.435294 0.337255
0.513726 0.447059 0.349020
0.513726 0.447059 0.380392
0.513726 0.458824 0.396078
0.513726 0.478431 0.450980
0.517647 0.415686 0.301961
0.517647 0.419608 0.262745
0.517647 0.419608 0.301961
0.517647 0.419608 0.305882
0.517647 0.419608 0.309804
0.517647 0.419608 0.313726
0.517647 0.423529 0.290196
0.517647 0.423529 0.321569
0.517647 0.423529 0.329412
0.517647 0.427451 0.294118
0.517647 0.427451 0.305882
0.517647 0.439216 0.282353
0.517647 0.454902 0.360784
0.517647 0.458824 0.396078
0.517647 0.513726 0.494118
0.521569 0.403922 0.270588
0.521569 0.407843 0.294118
0.521569 0.423529 0.258824
0.521569 0.423529 0.266667
0.521569 0.423529 0.270588
0.521569 0.423529 0.298039
0.521569 0.423529 0.301961
0.521569 0.427451 0.294118
0.521569 0.427451 0.305882
0.521569 0.427451 0.321569
0.521569 0.435294 0.274510
0.521569 0.447059 0.337255
0.525490 0.423529 0.309804
0.525490 0.427451 0.309804
0.525490 0.431373 0.262745
0.525490 0.431373 0.290196
0.525490 0.431373 0.298039
0.525490 0.431373 0.309804
0.525490 0.431373 0.313726
0.525490 0.435294 0.282353
0.525490 0.447059 0.349020
0.525490 0.454902 0.349020
0.525490 0.454902 0.360784
0.525490 0.458824 0.403922
0.525490 0.490196 0.423529
0.525490 0.525490 0.482353
0.529412 0.415686 0.262745
0.529412 0.427451 0.341176
0.529412 0.431373 0.266667
0.529412 0.431373 0.274510
0.529412 0.431373 0.282353
0.529412 0.431373 0.294118
0.529412 0.431373 0.301961
0.529412 0.431373 0.321569
0.529412 0.435294 0.294118
0.529412 0.435294 0.298039
0.529412 0.439216 0.309804
0.529412 0.443137 0.349020
0.529412 0.447059 0.305882
0.529412 0.462745 0.392157
0.529412 0.490196 0.447059
0.529412 0.537255 0.627451
0.533333 0.435294 0.274510
0.533333 0.435294 0.286275
0.533333 0.435294 0.313726
0.533333 0.439216 0.290196
0.533333 0.439216 0.294118
0.533333 0.466667 0.400000
0.533333 0.486275 0.423529
0.533333 0.490196 0.419608
0.537255 0.435294 0.301961
0.537255 0.435294 0.305882
0.537255 0.439216 0.298039
0.537255 0.439216 0.309804
0.537255 0.439216 0.325490
0.537255 0.439216 0.337255
0.537255 0.443137 0.301961
0.537255 0.443137 0.305882
0.537255 0.443137 0.321569
0.537255 0.458824 0.352941
0.537255 0.474510 0.411765
0.537255 0.482353 0.431373
0.537255 0.529412 0.568627
0.541176 0.439216 0.317647
0.541176 0.443137 0.313726
0.541176 0.443137 0.325490
0.541176 0.443137 0.329412
0.541176 0.447059 0.329412
0.541176 0.454902 0.301961
0.541176 0.458824 0.337255
0.541176 0.478431 0.419608
0.541176 0.490196 0.435294
0.541176 0.494118 0.431373
0.541176 0.521569 0.498039
0.545098 0.447059 0.294118
0.545098 0.447059 0.329412
0.545098 0.450980 0.309804
0.549020 0.435294 0.309804
0.549020 0.450980 0.329412
0.549020 0.454902 0.321569
0.549020 0.462745 0.345098
0.549020 0.474510 0.407843
0.549020 0.509804 0.482353
0.549020 0.513726 0.494118
0.549020 0.521569 0.498039
0.552941 0.419608 0.309804
0.552941 0.454902 0.313726
0.552941 0.458824 0.313726
0.552941 0.462745 0.337255
0.552941 0.498039 0.454902
0.552941 0.513726 0.545098
0.552941 0.529412 0.525490
0.556863 0.427451 0.329412
0.556863 0.450980 0.325490
0.556863 0.454902 0.356863
0.556863 0.462745 0.321569
0.556863 0.541176 0.537255
0.560784 0.462745 0.325490
0.560784 0.462745 0.341176
0.560784 0.466667 0.341176
0.560784 0.505882 0.458824
0.560784 0.556863 0.549020
0.564706 0.450980 0.290196
0.564706 0.458824 0.290196
0.564706 0.458824 0.325490
0.564706 0.462745 0.333333
0.564706 0.466667 0.290196
0.564706 0.466667 0.380392
0.564706 0.470588 0.329412
0.564706 0.470588 0.337255
0.564706 0.470588 0.352941
0.564706 0.501961 0.450980
0.564706 0.525490 0.486275
0.564706 0.525490 0.549020
0.568627 0.462745 0.298039
0.568627 0.462745 0.349020
0.568627 0.486275 0.360784
0.568627 0.494118 0.364706
0.568627 0.501961 0.427451
0.572549 0.466667 0.356863
0.572549 0.478431 0.360784
0.572549 0.486275 0.388235
0.572549 0.498039 0.364706
0.572549 0.505882 0.376471
0.572549 0.521569 0.458824
0.572549 0.521569 0.462745
0.572549 0.525490 0.466667
0.572549 0.537255 0.513726
0.576471 0.478431 0.325490
0.576471 0.482353 0.349020
0.576471 0.482353 0.356863
0.576471 0.486275 0.364706
0.576471 0.525490 0.462745
0.576471 0.529412 0.474510
0.576471 0.537255 0.498039
0.580392 0.486275 0.364706
0.580392 0.529412 0.458824
0.580392 0.545098 0.513726
0.580392 0.545098 0.537255
0.584314 0.470588 0.305882
0.584314 0.470588 0.372549
0.584314 0.490196 0.384314
0.584314 0.498039 0.380392
0.584314 0.498039 0.400000
0.588235 0.474510 0.317647
0.588235 0.490196 0.352941
0.588235 0.498039 0.372549
0.588235 0.525490 0.407843
0.588235 0.525490 0.427451
0.588235 0.533333 0.482353
0.588235 0.568627 0.556863
0.588235 0.600000 0.650980
0.592157 0.470588 0.290196
0.592157 0.494118 0.372549
0.592157 0.498039 0.352941
0.592157 0.498039 0.384314
0.592157 0.517647 0.380392
0.592157 0.541176 0.482353
0.592157 0.560784 0.537255
0.592157 0.576471 0.556863
0.596078 0.505882 0.368627
0.596078 0.509804 0.388235
0.596078 0.564706 0.552941
0.596078 0.568627 0.580392
0.600000 0.490196 0.341176
0.600000 0.494118 0.329412
0.600000 0.498039 0.376471
0.600000 0.513726 0.419608
0.600000 0.552941 0.490196
0.600000 0.580392 0.564706
0.600000 0.615686 0.686275
0.603922 0.505882 0.407843
0.603922 0.564706 0.525490
0.603922 0.615686 0.658824
0.607843 0.490196 0.337255
0.607843 0.501961 0.341176
0.607843 0.505882 0.384314
0.607843 0.580392 0.552941
0.611765 0.498039 0.349020
0.611765 0.509804 0.376471
0.611765 0.509804 0.388235
0.611765 0.513726 0.400000
0.611765 0.529412 0.423529
0.611765 0.580392 0.537255
0.611765 0.580392 0.541176
0.611765 0.592157 0.572549
0.611765 0.596078 0.584314
0.615686 0.533333 0.431373
0.615686 0.580392 0.560784
0.615686 0.584314 0.545098
0.615686 0.607843 0.619608
0.619608 0.494118 0.337255
0.619608 0.501961 0.400000
0.619608 0.521569 0.388235
0.619608 0.521569 0.403922
0.619608 0.576471 0.552941
0.619608 0.603922 0.588235
0.619608 0.611765 0.631373
0.619608 0.635294 0.678431
0.623529 0.498039 0.349020
0.623529 0.513726 0.325490
0.623529 0.517647 0.427451
0.623529 0.521569 0.407843
0.623529 0.533333 0.407843
0.623529 0.545098 0.447059
0.623529 0.580392 0.541176
0.623529 0.584314 0.541176
0.623529 0.592157 0.552941
0.623529 0.615686 0.611765
0.627451 0.529412 0.407843
0.627451 0.537255 0.376471
0.627451 0.556863 0.462745
0.627451 0.568627 0.549020
0.627451 0.588235 0.541176
0.627451 0.588235 0.552941
0.631373 0.513726 0.341176
0.631373 0.525490 0.352941
0.631373 0.576471 0.525490
0.631373 0.576471 0.533333
0.631373 0.580392 0.545098
0.631373 0.584314 0.517647
0.631373 0.607843 0.576471
0.631373 0.615686 0.580392
0.631373 0.615686 0.592157
0.631373 0.619608 0.603922
0.635294 0.513726 0.341176
0.635294 0.517647 0.372549
0.635294 0.584314 0.541176
0.635294 0.596078 0.560784
0.635294 0.600000 0.533333
0.635294 0.603922 0.572549
0.635294 0.607843 0.600000
0.635294 0.611765 0.576471
0.639216 0.525490 0.356863
0.639216 0.533333 0.400000
0.639216 0.541176 0.407843
0.639216 0.545098 0.411765
0.639216 0.549020 0.450980
0.639216 0.556863 0.450980
0.639216 0.564706 0.439216
0.639216 0.592157 0.533333
0.643137 0.521569 0.372549
0.643137 0.525490 0.352941
0.643137 0.529412 0.368627
0.643137 0.529412 0.388235
0.643137 0.541176 0.407843
0.643137 0.541176 0.415686
0.643137 0.541176 0.435294
0.643137 0.556863 0.435294
0.643137 0.556863 0.470588
0.643137 0.564706 0.435294
0.643137 0.572549 0.470588
0.643137 0.596078 0.552941
0.643137 0.603922 0.537255
0.643137 0.611765 0.576471
0.643137 0.654902 0.709804
0.647059 0.549020 0.400000
0.647059 0.552941 0.431373
0.647059 0.556863 0.392157
0.647059 0.556863 0.415686
0.647059 0.576471 0.509804
0.647059 0.588235 0.537255
0.647059 0.600000 0.525490
0.647059 0.603922 0.580392
0.647059 0.611765 0.541176
0.647059 0.611765 0.545098
0.647059 0.611765 0.611765
0.647059 0.615686 0.572549
0.647059 0.615686 0.576471
0.647059 0.654902 0.709804
0.650980 0.525490 0.368627
0.650980 0.541176 0.360784
0.650980 0.552941 0.431373
0.650980 0.556863 0.407843
0.650980 0.572549 0.474510
0.650980 0.596078 0.556863
0.650980 0.639216 0.631373
0.650980 0.650980 0.686275
0.654902 0.541176 0.384314
0.654902 0.545098 0.368627
0.654902 0.549020 0.443137
0.654902 0.549020 0.454902
0.654902 0.552941 0.427451
0.654902 0.552941 0.439216
0.654902 0.556863 0.396078
0.654902 0.556863 0.439216
0.654902 0.560784 0.423529
0.654902 0.560784 0.427451
0.654902 0.564706 0.407843
0.654902 0.568627 0.474510
0.654902 0.600000 0.533333
0.654902 0.615686 0.580392
0.654902 0.619608 0.600000
0.654902 0.623529 0.580392
0.654902 0.623529 0.584314
0.654902 0.639216 0.647059
0.658824 0.545098 0.400000
0.658824 0.556863 0.427451
0.658824 0.556863 0.435294
0.658824 0.607843 0.572549
0.658824 0.631373 0.596078
0.658824 0.658824 0.690196
0.662745 0.537255 0.341176
0.662745 0.541176 0.423529
0.662745 0.549020 0.396078
0.662745 0.560784 0.427451
0.662745 0.564706 0.443137
0.662745 0.568627 0.403922
0.662745 0.611765 0.564706
0.662745 0.635294 0.682353
0.662745 0.647059 0.631373
0.666667 0.533333 0.396078
0.666667 0.552941 0.427451
0.666667 0.556863 0.376471
0.666667 0.556863 0.411765
0.666667 0.564706 0.423529
0.666667 0.568627 0.407843
0.666667 0.568627 0.447059
0.666667 0.572549 0.439216
0.666667 0.572549 0.462745
0.666667 0.576471 0.462745
0.666667 0.584314 0.470588
0.666667 0.647059 0.635294
0.670588 0.541176 0.376471
0.670588 0.545098 0.403922
0.670588 0.552941 0.407843
0.670588 0.556863 0.403922
0.670588 0.556863 0.419608
0.670588 0.556863 0.423529
0.670588 0.560784 0.415686
0.670588 0.564706 0.415686
0.670588 0.576471 0.466667
0.670588 0.580392 0.478431
0.670588 0.635294 0.607843
0.670588 0.639216 0.600000
0.670588 0.643137 0.611765
0.670588 0.654902 0.631373
0.670588 0.678431 0.725490
0.674510 0.560784 0.392157
0.674510 0.564706 0.415686
0.674510 0.564706 0.419608
0.674510 0.568627 0.403922
0.674510 0.576471 0.454902
0.674510 0.580392 0.423529
0.674510 0.580392 0.431373
0.674510 0.580392 0.447059
0.674510 0.584314 0.450980
0.674510 0.588235 0.462745
0.674510 0.619608 0.513726
0.674510 0.635294 0.627451
0.674510 0.647059 0.674510
0.674510 0.650980 0.623529
0.674510 0.650980 0.650980
0.674510 0.654902 0.635294
0.674510 0.666667 0.666667
0.678431 0.564706 0.427451
0.678431 0.564706 0.443137
0.678431 0.576471 0.447059
0.678431 0.580392 0.431373
0.678431 0.580392 0.435294
0.678431 0.580392 0.470588
0.678431 0.584314 0.447059
0.678431 0.584314 0.450980
0.678431 0.584314 0.486275
0.678431 0.592157 0.454902
0.678431 0.592157 0.462745
0.678431 0.603922 0.490196
0.678431 0.635294 0.592157
0.678431 0.654902 0.654902
0.678431 0.658824 0.627451
0.678431 0.662745 0.647059
0.678431 0.701961 0.725490
0.682353 0.568627 0.427451
0.682353 0.576471 0.435294
0.682353 0.576471 0.447059
0.682353 0.580392 0.450980
0.682353 0.584314 0.443137
0.682353 0.592157 0.490196
0.682353 0.600000 0.474510
0.682353 0.619608 0.529412
0.682353 0.643137 0.603922
0.682353 0.654902 0.615686
0.682353 0.666667 0.654902
0.682353 0.666667 0.670588
0.682353 0.686275 0.717647
0.686275 0.584314 0.447059
0.686275 0.588235 0.423529
0.686275 0.592157 0.482353
0.686275 0.600000 0.454902
0.686275 0.600000 0.478431
0.686275 0.600000 0.494118
0.686275 0.607843 0.509804
0.686275 0.635294 0.603922
0.686275 0.647059 0.627451
0.686275 0.662745 0.639216
0.690196 0.584314 0.431373
0.690196 0.588235 0.450980
0.690196 0.588235 0.486275
0.690196 0.592157 0.443137
0.690196 0.592157 0.474510
0.690196 0.592157 0.482353
0.690196 0.596078 0.447059
0.690196 0.596078 0.454902
0.690196 0.600000 0.466667
0.690196 0.607843 0.498039
0.690196 0.662745 0.592157
0.690196 0.670588 0.643137
0.690196 0.682353 0.705882
0.694118 0.576471 0.427451
0.694118 0.584314 0.450980
0.694118 0.588235 0.474510
0.694118 0.592157 0.450980
0.694118 0.596078 0.439216
0.694118 0.596078 0.466667
0.694118 0.596078 0.478431
0.694118 0.600000 0.458824
0.694118 0.600000 0.478431
0.694118 0.611765 0.498039
0.694118 0.662745 0.619608
0.694118 0.666667 0.650980
0.694118 0.690196 0.709804
0.698039 0.600000 0.439216
0.698039 0.600000 0.474510
0.698039 0.603922 0.470588
0.698039 0.603922 0.498039
0.698039 0.607843 0.486275
0.698039 0.611765 0.490196
0.698039 0.611765 0.494118
0.698039 0.611765 0.505882
0.698039 0.619608 0.482353
0.698039 0.658824 0.627451
0.698039 0.694118 0.717647
0.701961 0.603922 0.513726
0.701961 0.623529 0.494118
0.701961 0.666667 0.639216
0.701961 0.670588 0.631373
0.701961 0.686275 0.670588
0.701961 0.690196 0.654902
0.701961 0.701961 0.737255
0.705882 0.607843 0.490196
0.705882 0.611765 0.498039
0.705882 0.639216 0.564706
0.705882 0.666667 0.639216
0.705882 0.666667 0.658824
0.705882 0.678431 0.654902
0.705882 0.678431 0.666667
0.705882 0.686275 0.650980
0.705882 0.686275 0.662745
0.705882 0.686275 0.670588
0.705882 0.686275 0.678431
0.705882 0.690196 0.686275
0.705882 0.701961 0.705882
0.705882 0.721569 0.756863
0.709804 0.600000 0.454902
0.709804 0.611765 0.490196
0.709804 0.611765 0.501961
0.709804 0.627451 0.513726
0.709804 0.643137 0.580392
0.709804 0.654902 0.603922
0.709804 0.658824 0.623529
0.709804 0.678431 0.631373
0.709804 0.694118 0.682353
0.709804 0.698039 0.686275
0.709804 0.701961 0.713726
0.709804 0.701961 0.784314
0.709804 0.705882 0.752941
0.713726 0.607843 0.494118
0.713726 0.619608 0.498039
0.713726 0.619608 0.509804
0.713726 0.631373 0.517647
0.713726 0.678431 0.658824
0.713726 0.686275 0.662745
0.713726 0.717647 0.764706
0.713726 0.741176 0.784314
0.717647 0.615686 0.478431
0.717647 0.615686 0.490196
0.717647 0.619608 0.470588
0.717647 0.623529 0.494118
0.717647 0.631373 0.513726
0.717647 0.682353 0.658824
0.717647 0.694118 0.694118
0.717647 0.701961 0.666667
0.717647 0.713726 0.737255
0.721569 0.623529 0.501961
0.721569 0.627451 0.486275
0.721569 0.627451 0.494118
0.721569 0.631373 0.509804
0.721569 0.725490 0.800000
0.721569 0.737255 0.776471
0.721569 0.752941 0.803922
0.725490 0.623529 0.486275
0.725490 0.623529 0.501961
0.725490 0.627451 0.513726
0.725490 0.635294 0.509804
0.725490 0.650980 0.521569
0.725490 0.725490 0.764706
0.729412 0.607843 0.470588
0.729412 0.611765 0.470588
0.729412 0.631373 0.513726
0.729412 0.698039 0.654902
0.729412 0.709804 0.698039
0.729412 0.741176 0.807843
0.733333 0.635294 0.490196
0.733333 0.635294 0.513726
0.733333 0.643137 0.521569
0.733333 0.694118 0.654902
0.733333 0.705882 0.682353
0.733333 0.721569 0.745098
0.737255 0.635294 0.529412
0.737255 0.639216 0.517647
0.737255 0.643137 0.533333
0.737255 0.650980 0.541176
0.737255 0.654902 0.541176
0.737255 0.717647 0.698039
0.737255 0.717647 0.701961
0.737255 0.717647 0.705882
0.737255 0.745098 0.811765
0.741176 0.627451 0.478431
0.741176 0.635294 0.498039
0.741176 0.643137 0.521569
0.741176 0.647059 0.509804
0.741176 0.647059 0.529412
0.741176 0.776471 0.811765
0.745098 0.635294 0.509804
0.745098 0.639216 0.466667
0.745098 0.643137 0.513726
0.745098 0.647059 0.517647
0.745098 0.647059 0.533333
0.745098 0.654902 0.529412
0.745098 0.725490 0.709804
0.749020 0.631373 0.462745
0.749020 0.647059 0.533333
0.749020 0.650980 0.501961
0.749020 0.650980 0.529412
0.749020 0.650980 0.533333
0.749020 0.658824 0.513726
0.749020 0.658824 0.529412
0.749020 0.662745 0.537255
0.749020 0.729412 0.705882
0.749020 0.729412 0.745098
0.749020 0.745098 0.749020
0.749020 0.745098 0.764706
0.749020 0.760784 0.807843
0.749020 0.776471 0.819608
0.752941 0.650980 0.529412
0.752941 0.654902 0.525490
0.752941 0.654902 0.533333
0.752941 0.654902 0.537255
0.752941 0.662745 0.537255
0.752941 0.662745 0.541176
0.756863 0.643137 0.490196
0.756863 0.654902 0.525490
0.756863 0.666667 0.529412
0.756863 0.666667 0.541176
0.756863 0.670588 0.533333
0.756863 0.725490 0.694118
0.756863 0.749020 0.749020
0.756863 0.756863 0.792157
0.760784 0.647059 0.521569
0.760784 0.650980 0.513726
0.760784 0.654902 0.533333
0.760784 0.658824 0.529412
0.760784 0.662745 0.537255
0.760784 0.670588 0.545098
0.760784 0.670588 0.549020
0.760784 0.674510 0.552941
0.760784 0.674510 0.592157
0.760784 0.737255 0.725490
0.760784 0.749020 0.745098
0.760784 0.764706 0.784314
0.764706 0.658824 0.545098
0.764706 0.670588 0.529412
0.764706 0.670588 0.545098
0.764706 0.670588 0.560784
0.764706 0.745098 0.729412
0.768627 0.666667 0.545098
0.768627 0.678431 0.552941
0.768627 0.768627 0.780392
0.772549 0.662745 0.549020
0.772549 0.670588 0.549020
0.772549 0.674510 0.545098
0.772549 0.674510 0.552941
0.772549 0.686275 0.560784
0.772549 0.690196 0.545098
0.772549 0.694118 0.623529
0.772549 0.745098 0.717647
0.776471 0.670588 0.537255
0.776471 0.678431 0.517647
0.776471 0.678431 0.549020
0.776471 0.678431 0.560784
0.776471 0.682353 0.541176
0.776471 0.686275 0.537255
0.776471 0.686275 0.564706
0.776471 0.690196 0.545098
0.776471 0.760784 0.752941
0.776471 0.776471 0.835294
0.776471 0.792157 0.839216
0.776471 0.800000 0.850980
0.776471 0.815686 0.862745
0.780392 0.682353 0.560784
0.780392 0.686275 0.537255
0.780392 0.686275 0.552941
0.780392 0.690196 0.564706
0.780392 0.741176 0.737255
0.780392 0.749020 0.713726
0.780392 0.760784 0.737255
0.780392 0.764706 0.741176
0.780392 0.788235 0.831373
0.784314 0.670588 0.552941
0.784314 0.686275 0.564706
0.784314 0.686275 0.568627
0.784314 0.690196 0.552941
0.784314 0.690196 0.568627
0.784314 0.788235 0.858824
0.788235 0.694118 0.560784
0.788235 0.725490 0.592157
0.788235 0.792157 0.839216
0.792157 0.662745 0.470588
0.792157 0.670588 0.517647
0.792157 0.698039 0.564706
0.796078 0.694118 0.572549
0.796078 0.698039 0.568627
0.796078 0.698039 0.576471
0.796078 0.698039 0.580392
0.796078 0.772549 0.749020
0.796078 0.780392 0.768627
0.796078 0.788235 0.792157
0.800000 0.721569 0.592157
0.803922 0.815686 0.839216
0.807843 0.807843 0.827451
0.807843 0.811765 0.858824
0.807843 0.823529 0.870588
0.811765 0.705882 0.521569
0.811765 0.780392 0.768627
0.811765 0.835294 0.894118
0.815686 0.811765 0.866667
0.815686 0.815686 0.843137
0.819608 0.827451 0.874510
0.823529 0.823529 0.831373
0.823529 0.847059 0.929412
0.827451 0.725490 0.592157
0.827451 0.843137 0.886275
0.831373 0.796078 0.788235
0.831373 0.815686 0.811765
0.850980 0.862745 0.905882
0.854902 0.839216 0.835294
0.854902 0.854902 0.870588
0.862745 0.870588 0.913725
0.866667 0.858824 0.878431
0.870588 0.882353 0.921569
0.874510 0.898039 0.929412
0.878431 0.890196 0.945098
0.890196 0.890196 0.890196
0.898039 0.886275 0.890196
0.898039 0.886275 0.905882
0.898039 0.890196 0.890196
0.898039 0.913725 0.952941
0.901961 0.898039 0.913725
0.909804 0.921569 0.956863
0.913725 0.913725 0.921569
0.925490 0.921569 0.941176
0.929412 0.933333 0.937255
0.929412 0.949020 0.972549
0.937255 0.956863 0.968627
0.960784 0.980392 0.972549
0 0 19 690 92
0 0 20 880 28
0 0 21 820 28
0 0 22 926 28
0 0 23 1152 60
1 0 16 1060 92
1 0 17 993 28
1 0 18 478 20
1 0 19 558 16
1 0 20 724 24
1 0 21 842 24
1 0 22 979 24
1 0 23 1202 56
1 1 18 1369 76
1 1 19 1327 44
2 0 13 1059 92
2 0 14 1092 28
2 0 15 940 20
2 0 16 604 16
2 0 17 550 16
2 0 18 577 16
2 0 19 617 16
2 0 20 712 16
2 0 21 846 24
2 0 22 927 24
2 0 23 1092 24
2 0 24 1257 60
2 1 15 1347 76
2 1 16 1377 12
2 1 17 1388 12
2 1 18 1360 8
2 1 19 1415 8
2 1 20 1429 44
3 0 10 673 92
3 0 11 997 28
3 0 12 709 20
3 0 13 822 16
3 0 14 771 16
3 0 15 741 16
3 0 16 661 16
3 0 17 640 16
3 0 18 620 16
3 0 19 672 16
3 0 20 745 16
3 0 21 840 24
3 0 22 953 24
3 0 23 1081 24
3 0 24 1203 56
3 1 12 1478 76
3 1 13 1459 12
3 1 14 1390 12
3 1 15 1401 8
3 1 16 1320 8
3 1 17 1358 8
3 1 18 1338 8
3 1 19 1280 8
3 1 20 1389 42
4 0 7 804 92
4 0 8 789 20
4 0 9 936 20
4 0 10 603 16
4 0 11 611 16
4 0 12 707 16
4 0 13 722 16
4 0 14 741 16
4 0 15 727 16
4 0 16 700 16
4 0 17 675 16
4 0 18 677 16
4 0 19 743 16
4 0 20 785 24
4 0 21 862 24
4 0 22 970 24
4 0 23 1036 24
4 0 24 1299 56
4 1 8 1231 76
4 1 9 1485 12
4 1 10 1510 12
4 1 11 1480 12
4 1 12 1465 8
4 1 13 1438 8
4 1 14 1400 8
4 1 15 1400 8
4 1 16 1351 8
4 1 17 1242 8
4 1 18 1250 8
4 1 19 1235 40
4 9 14 518 124
5 0 5 1089 84
5 0 6 1056 20
5 0 7 882 16
5 0 8 759 16
5 0 9 797 16
5 0 10 754 16
5 0 11 683 16
5 0 12 685 16
5 0 13 701 16
5 0 14 714 16
5 0 15 740 16
5 0 16 714 16
5 0 17 722 16
5 0 18 742 16
5 0 19 765 16
5 0 20 803 16
5 0 21 843 24
5 0 22 925 24
5 0 23 1026 24
5 0 24 1076 24
5 0 25 1240 60
5 1 5 1272 76
5 1 6 1486 12
5 1 7 1512 12
5 1 8 1452 8
5 1 9 1484 8
5 1 10 1470 8
5 1 11 1495 8
5 1 12 1472 8
5 1 13 1439 8
5 1 14 1417 8
5 1 15 1365 8
5 1 16 1280 8
5 1 17 1210 8
5 1 18 513 8
5 1 19 580 8
5 1 20 1324 44
5 7 13 504 84
5 7 14 451 54
5 8 13 145 68
5 8 14 552 38
5 9 13 207 68
5 9 14 625 34
5 10 13 58 68
5 10 14 525 38
5 11 13 91 76
5 11 14 511 38
5 12 14 137 70
5 12 15 593 54
5 13 14 172 76
5 13 15 421 46
5 27 20 438 116
5 28 20 484 108
6 0 2 1003 84
6 0 3 1035 20
6 0 4 1047 20
6 0 5 995 16
6 0 6 968 16
6 0 7 852 16
6 0 8 816 16
6 0 9 796 16
6 0 10 746 16
6 0 11 747 16
6 0 12 708 16
6 0 13 720 16
6 0 14 728 16
6 0 15 727 16
6 0 16 727 16
6 0 17 727 16
6 0 18 750 16
6 0 19 774 16
6 0 20 827 16
6 0 21 865 16
6 0 22 951 24
6 0 23 974 24
6 0 24 1080 24
6 0 25 1194 56
6 1 2 1491 76
6 1 3 1532 12
6 1 4 1531 12
6 1 5 1543 8
6 1 6 1549 8
6 1 7 1569 8
6 1 8 1553 8
6 1 9 1526 8
6 1 10 1524 8
6 1 11 1489 8
6 1 12 1473 8
6 1 13 1447 8
6 1 14 1386 8
6 1 15 1378 8
6 1 16 1293 8
6 1 17 374 8
6 1 18 334 8
6 1 19 239 8
6 1 20 509 8
6 1 21 1371 44
6 7 12 420 86
6 7 13 410 50
6 8 12 244 70
6 8 13 472 34
6 9 12 581 70
6 9 13 443 34
6 10 12 146 68
6 10 13 370 32
6 11 12 123 76
6 11 13 645 32
6 12 13 612 100
6 13 13 25 70
6 13 14 446 48
6 14 13 227 78
6 14 14 330 36
6 15 14 1477 108
6 26 20 215 118
6 27 20 175 96
6 28 20 151 104
7 0 0 1106 84
7 0 1 1058 20
7 0 2 1013 16
7 0 3 1007 16
7 0 4 992 16
7 0 5 966 16
7 0 6 902 16
7 0 7 893 16
7 0 8 824 16
7 0 9 798 16
7 0 10 772 16
7 0 11 748 16
7 0 12 739 16
7 0 13 713 16
7 0 14 714 16
7 0 15 720 16
7 0 16 727 16
7 0 17 751 16
7 0 18 757 16
7 0 19 774 16
7 0 20 807 16
7 0 21 856 16
7 0 22 900 24
7 0 23 949 24
7 0 24 1027 24
7 0 25 1291 56
7 1 0 1547 76
7 1 1 1523 12
7 1 2 1562 8
7 1 3 1562 8
7 1 4 1575 8
7 1 5 1541 8
7 1 6 1560 8
7 1 7 1537 8
7 1 8 1514 8
7 1 9 1537 8
7 1 10 1492 8
7 1 11 1428 8
7 1 12 1459 8
7 1 13 1430 8
7 1 14 1348 8
7 1 15 1199 8
7 1 16 841 10
7 1 17 429 8
7 1 18 477 8
7 1 19 380 8
7 1 20 333 8
7 1 21 1198 40
7 9 14 918 86
7 9 15 1022 54
7 10 12 522 82
7 10 13 732 16
7 10 14 142 6
7 10 15 345 38
7 11 12 1051 64
7 11 13 549 2
7 11 14 212 6
7 11 15 209 6
7 11 16 1149 54
7 12 12 219 68
7 12 13 543 10
7 12 14 232 6
7 12 15 169 6
7 12 16 960 38
7 13 12 104 102
7 13 14 242 66
7 13 15 90 6
7 13 16 308 6
7 13 17 1150 54
7 14 12 157 102
7 14 14 59 66
7 14 15 119 6
7 14 16 1057 6
7 14 17 1147 6
7 14 18 1329 54
7 15 12 97 76
7 15 13 120 30
7 15 14 407 10
7 15 15 401 6
7 15 16 910 6
7 15 17 1192 6
7 15 18 1271 38
7 16 15 453 70
7 16 16 362 6
7 16 17 1062 6
7 16 18 1184 38
7 17 15 418 78
7 17 16 381 6
7 17 17 406 6
7 17 18 1343 38
7 18 16 459 70
7 18 17 341 6
7 18 18 1392 46
7 19 16 1586 78
7 19 17 528 46
7 27 19 270 86
7 27 20 105 48
7 28 19 392 70
7 28 20 332 40
7 29 19 1053 110
8 0 0 1069 80
8 0 1 1037 16
8 0 2 1017 16
8 0 3 976 16
8 0 4 952 16
8 0 5 913 16
8 0 6 883 16
8 0 7 849 16
8 0 8 810 16
8 0 9 779 16
8 0 10 772 16
8 0 11 755 16
8 0 12 739 16
8 0 13 719 16
8 0 14 720 16
8 0 15 720 16
8 0 16 740 24
8 0 17 751 16
8 0 18 762 16
8 0 19 784 16
8 0 20 812 16
8 0 21 839 16
8 0 22 884 24
8 0 23 950 24
8 0 24 921 24
8 0 25 872 24
8 0 26 1020 60
8 1 0 1542 72
8 1 1 1513 8
8 1 2 1570 8
8 1 3 1588 8
8 1 4 1563 8
8 1 5 1571 8
8 1 6 1583 8
8 1 7 1550 8
8 1 8 1540 8
8 1 9 1507 8
8 1 10 1482 8
8 1 11 1453 8
8 1 12 1387 8
8 1 13 1244 8
8 1 14 1132 0
8 1 15 831 34
8 1 17 359 72
8 1 18 94 8
8 1 19 236 8
8 1 20 1281 8
8 1 21 1259 40
8 2 14 447 70
8 2 15 307 14
8 2 16 395 60
8 3 14 1087 102
8 4 14 681 102
8 5 13 1172 84
8 5 14 1109 6
8 5 15 562 54
8 6 13 705 70
8 6 14 793 6
8 6 15 1093 6
8 6 16 1110 54
8 7 13 322 70
8 7 14 1079 6
8 7 15 1043 6
8 7 16 1133 38
8 8 13 396 70
8 8 14 1221 14
8 8 15 1050 14
8 8 16 1225 6
8 8 17 1179 54
8 9 13 129 102
8 9 16 1088 70
8 9 17 1224 38
8 10 13 382 106
8 10 16 1182 78
8 10 17 1252 38
8 11 12 205 112
8 11 17 1215 70
8 11 18 1175 54
8 12 11 769 86
8 12 12 879 40
8 12 17 1229 78
8 12 18 1260 38
8 13 11 127 100
8 13 18 1354 78
8 13 19 1405 54
8 14 11 32 108
8 14 19 1404 102
8 15 12 163 114
8 15 19 1490 102
8 16 12 263 76
8 16 13 833 22
8 16 14 1151 54
8 16 19 1406 70
8 16 20 1475 54
8 17 13 389 70
8 17 14 1564 38
8 17 19 1424 70
8 17 20 1502 38
8 18 13 570 78
8 18 14 1120 6
8 18 15 1535 54
8 18 19 1577 70
8 18 20 1517 38
8 19 14 349 78
8 19 15 499 38
8 19 18 1456 86
8 19 19 1610 6
8 19 20 1592 38
8 20 15 794 78
8 20 16 1616 22
8 20 17 1443 22
8 20 18 559 6
8 20 19 452 6
8 20 20 1530 38
8 21 16 823 78
8 21 17 1605 14
8 21 18 575 6
8 21 19 706 6
8 21 20 413 38
8 22 18 1607 78
8 22 19 1567 6
8 22 20 1518 38
8 23 19 1609 78
8 23 20 1591 46
8 26 18 514 84
8 26 19 494 30
8 26 20 425 54
8 27 18 415 102
8 27 20 858 98
8 28 18 317 102
8 28 20 689 98
8 29 18 9 102
8 29 20 610 102
8 30 18 1295 78
8 30 19 200 30
8 30 20 275 46
9 0 0 929 82
9 0 1 996 16
9 0 2 1018 16
9 0 3 977 16
9 0 4 938 16
9 0 5 901 16
9 0 6 863 16
9 0 7 836 16
9 0 8 819 16
9 0 9 780 16
9 0 10 772 16
9 0 11 755 16
9 0 12 720 16
9 0 13 720 16
9 0 14 720 16
9 0 15 714 24
9 0 16 727 16
9 0 17 751 16
9 0 18 757 16
9 0 19 784 16
9 0 20 812 16
9 0 21 844 16
9 0 22 864 24
9 0 23 896 24
9 0 24 921 24
9 0 25 946 24
9 0 26 1137 56
9 1 0 1263 74
9 1 1 1572 8
9 1 2 1580 8
9 1 3 1573 8
9 1 4 1536 8
9 1 5 1582 8
9 1 6 1571 8
9 1 7 1539 8
9 1 8 1515 8
9 1 9 1495 8
9 1 10 1488 8
9 1 11 1375 8
9 1 12 1267 8
9 1 13 1005 0
9 1 14 937 40
9 1 16 319 68
9 1 17 592 8
9 1 18 419 8
9 1 19 468 8
9 1 20 1163 8
9 1 21 1241 40
9 2 13 619 100
9 2 16 273 106
9 3 13 1042 102
9 3 15 624 116
9 4 13 1165 102
9 4 15 944 110
9 5 13 1212 106
9 5 16 1086 126
9 6 12 1309 118
9 6 17 1118 118
9 7 12 1340 102
9 7 17 1188 78
9 7 18 1166 52
9 8 12 510 102
9 8 18 1228 102
9 9 12 229 102
9 9 18 1328 102
9 10 12 597 102
9 10 18 1396 78
9 10 19 1294 52
9 11 12 1146 98
9 11 19 1408 102
9 12 12 909 98
9 12 19 1391 110
9 13 11 411 80
9 13 12 1052 46
9 13 20 1431 116
9 14 11 231 96
9 14 20 1313 102
9 15 11 391 108
9 15 20 1440 110
9 16 12 325 112
9 16 21 1528 116
9 17 12 193 100
9 17 21 1599 100
9 18 12 384 108
9 18 21 1619 100
9 19 13 441 126
9 19 21 1500 100
9 20 14 426 126
9 20 21 1501 102
9 21 15 501 126
9 21 21 423 102
9 22 16 734 94
9 22 17 1613 54
9 22 21 1574 102
9 23 17 1621 78
9 23 18 1614 54
9 23 21 1612 102
9 24 18 1618 70
9 24 19 1615 22
9 24 20 1608 22
9 24 21 1617 46
9 25 18 1476 70
9 25 19 531 14
9 25 20 1558 46
9 26 18 538 106
9 26 21 583 116
9 27 17 482 116
9 27 21 474 100
9 28 17 512 102
9 28 21 481 100
9 29 17 519 102
9 29 21 354 100
9 30 17 1587 108
9 30 21 1622 108
9 31 18 284 92
9 31 19 196 28
9 31 20 92 60
10 0 1 1040 80
10 0 2 1025 16
10 0 3 967 16
10 0 4 920 16
10 0 5 889 16
10 0 6 850 16
10 0 7 825 16
10 0 8 801 16
10 0 9 773 16
10 0 10 750 16
10 0 11 727 16
10 0 12 714 16
10 0 13 708 16
10 0 14 711 16
10 0 15 710 16
10 0 16 721 16
10 0 17 730 16
10 0 18 752 16
10 0 19 767 16
10 0 20 791 16
10 0 21 826 16
10 0 22 864 24
10 0 23 874 24
10 0 24 903 24
10 0 25 973 24
10 0 26 1136 56
10 1 1 1487 72
10 1 2 1533 8
10 1 3 1552 8
10 1 4 1551 8
10 1 5 1561 8
10 1 6 1505 8
10 1 7 1507 8
10 1 8 1522 8
10 1 9 1444 8
10 1 10 1248 8
10 1 11 1170 8
10 1 12 1096 8
10 1 13 1016 0
10 1 14 1418 0
10 1 15 584 4
10 1 16 758 8
10 1 17 1055 8
10 1 18 1469 8
10 1 19 1534 8
10 1 20 1416 8
10 1 21 1385 40
10 2 13 830 74
10 2 14 1402 12
10 2 15 149 38
10 3 12 439 118
10 3 15 591 104
10 4 12 364 102
10 4 16 868 126
10 5 12 485 110
10 5 17 1000 126
10 6 11 470 116
10 6 18 1097 116
10 7 11 268 100
10 7 18 1178 106
10 8 11 336 102
10 8 19 1269 116
10 9 11 348 102
10 9 19 1342 102
10 10 11 269 102
10 10 19 1366 106
10 11 11 130 100
10 11 20 1380 116
10 12 11 249 100
10 12 20 1395 102
10 13 11 371 96
10 13 20 1432 106
10 14 11 462 96
10 14 21 1420 116
10 15 11 563 104
10 15 21 1460 100
10 16 12 576 114
10 16 21 1566 98
10 17 12 189 98
10 17 21 1604 98
10 18 12 346 96
10 18 21 1603 98
10 19 12 321 108
10 19 21 1461 106
10 20 13 505 124
10 20 22 1227 116
10 21 14 390 126
10 21 22 520 100
10 22 15 497 126
10 22 22 1600 100
10 23 16 347 126
10 23 22 1624 100
10 24 17 1620 118
10 24 22 1625 108
10 25 17 1193 100
10 25 21 1623 116
10 26 17 311 100
10 26 21 1611 96
10 27 17 358 106
10 27 21 469 96
10 28 16 247 116
10 28 21 486 96
10 29 16 372 108
10 29 21 437 96
10 30 17 1565 112
10 30 21 274 104
10 31 17 1546 76
10 31 18 1516 24
10 31 19 252 24
10 31 20 1314 56
11 0 1 1070 80
11 0 2 1019 16
11 0 3 978 16
11 0 4 906 16
11 0 5 874 16
11 0 6 837 16
11 0 7 811 16
11 0 8 783 16
11 0 9 763 16
11 0 10 727 16
11 0 11 714 16
11 0 12 699 16
11 0 13 694 16
11 0 14 702 16
11 0 15 693 16
11 0 16 710 16
11 0 17 715 16
11 0 18 733 16
11 0 19 753 16
11 0 20 787 16
11 0 21 802 16
11 0 22 838 16
11 0 23 874 24
11 0 24 924 24
11 0 25 969 24
11 0 26 1014 24
11 0 27 1135 60
11 1 1 1506 72
11 1 2 1540 8
11 1 3 1521 8
11 1 4 1520 8
11 1 5 1511 8
11 1 6 1519 8
11 1 7 1437 8
11 1 8 1372 8
11 1 9 1258 8
11 1 10 1155 8
11 1 11 1116 8
11 1 12 1153 0
11 1 13 1527 8
11 1 14 1162 0
11 1 15 935 8
11 1 16 1012 8
11 1 17 1071 8
11 1 18 1208 8
11 1 19 1361 8
11 1 20 1321 8
11 1 21 1292 8
11 1 22 1282 44
11 2 12 988 110
11 2 14 1128 104
11 3 11 253 118
11 3 15 930 88
11 3 16 958 60
11 4 11 324 102
11 4 17 1031 124
11 5 11 461 102
11 5 18 1033 116
11 6 11 431 98
11 6 18 1072 106
11 7 11 366 106
11 7 19 1251 116
11 8 10 228 116
11 8 19 1201 106
11 9 10 283 100
11 9 20 1223 116
11 10 10 217 108
11 10 20 1353 100
11 11 11 218 114
11 11 20 1419 106
11 12 11 110 98
11 12 21 1442 116
11 13 11 147 98
11 13 21 1421 100
11 14 11 125 98
11 14 21 1466 98
11 15 11 166 96
11 15 21 1467 106
11 16 11 220 100
11 16 22 1594 116
11 17 11 273 108
11 17 22 1585 100
11 18 12 285 112
11 18 22 1555 100
11 19 12 314 104
11 19 22 1499 100
11 20 13 393 114
11 20 22 1538 96
11 21 13 313 108
11 21 22 495 96
11 22 14 233 124
11 22 22 1559 96
11 23 15 111 124
11 23 22 1602 98
11 24 16 467 124
11 24 22 1425 106
11 25 17 1606 112
11 25 21 1589 112
11 26 17 1296 104
11 26 21 1483 96
11 27 16 335 116
11 27 21 427 96
11 28 16 399 96
11 28 21 385 96
11 29 16 1138 104
11 29 21 397 96
11 30 17 1255 112
11 30 21 457 104
11 31 17 267 74
11 31 18 181 24
11 31 19 150 24
11 31 20 1237 56
12 0 1 1039 82
12 0 2 1028 16
12 0 3 948 16
12 0 4 894 16
12 0 5 855 16
12 0 6 819 16
12 0 7 799 16
12 0 8 781 16
12 0 9 760 16
12 0 10 720 16
12 0 11 708 16
12 0 12 691 16
12 0 13 678 16
12 0 14 687 16
12 0 15 679 16
12 0 16 693 16
12 0 17 703 16
12 0 18 715 16
12 0 19 744 16
12 0 20 763 16
12 0 21 792 16
12 0 22 829 16
12 0 23 854 24
12 0 24 886 24
12 0 25 916 24
12 0 26 1004 24
12 0 27 1105 56
12 1 1 1458 74
12 1 2 1479 8
12 1 3 1493 8
12 1 4 1463 8
12 1 5 1435 8
12 1 6 1376 8
12 1 7 1220 8
12 1 8 1249 8
12 1 9 1196 8
12 1 10 1122 8
12 1 11 1101 0
12 1 12 1046 10
12 1 13 1393 10
12 1 14 1054 0
12 1 15 961 8
12 1 16 1038 8
12 1 17 1065 8
12 1 18 1102 8
12 1 19 1142 8
12 1 20 1164 8
12 1 21 1148 8
12 1 22 1143 40
12 2 11 688 110
12 2 14 931 104
12 3 10 464 116
12 3 15 942 90
12 3 16 1032 56
12 4 10 279 102
12 4 17 972 120
12 5 10 408 102
12 5 18 1008 120
12 6 10 369 102
12 6 19 1001 116
12 7 10 257 102
12 7 19 1181 104
12 8 10 265 96
12 8 20 1214 116
12 9 10 137 96
12 9 20 1222 96
12 10 10 124 96
12 10 20 1379 104
12 11 10 132 100
12 11 21 1367 116
12 12 10 188 100
12 12 21 1341 96
12 13 10 113 100
12 13 21 1403 104
12 14 10 158 108
12 14 22 1398 116
12 15 11 48 112
12 15 22 1474 100
12 16 11 139 96
12 16 22 1407 96
12 17 11 167 104
12 17 22 1529 96
12 18 12 287 112
12 18 22 1597 96
12 19 12 367 96
12 19 22 1590 98
12 20 12 352 108
12 20 22 1270 98
12 21 13 299 120
12 21 22 507 98
12 22 14 357 120
12 22 22 1595 106
12 23 15 258 120
12 23 21 1556 118
12 24 16 444 122
12 24 21 1503 102
12 25 17 278 112
12 25 21 1568 98
12 26 17 1111 104
12 26 21 1468 96
12 27 16 1045 114
12 27 21 398 96
12 28 16 945 98
12 28 21 351 96
12 29 16 932 106
12 29 21 460 96
12 30 17 1074 120
12 30 21 1332 106
12 31 18 148 90
12 31 19 124 26
12 31 20 246 58
13 0 2 1015 80
13 0 3 914 16
13 0 4 873 16
13 0 5 836 16
13 0 6 805 16
13 0 7 781 16
13 0 8 741 16
13 0 9 720 16
13 0 10 708 16
13 0 11 686 16
13 0 12 669 24
13 0 13 662 24
13 0 14 662 16
13 0 15 653 16
13 0 16 667 16
13 0 17 676 16
13 0 18 694 16
13 0 19 723 16
13 0 20 752 16
13 0 21 784 16
13 0 22 821 16
13 0 23 853 24
13 0 24 895 24
13 0 25 923 24
13 0 26 990 24
13 0 27 1100 56
13 1 2 1373 72
13 1 3 1457 8
13 1 4 1414 8
13 1 5 1322 8
13 1 6 1290 8
13 1 7 1187 8
13 1 8 1160 8
13 1 9 1066 8
13 1 10 994 2
13 1 11 956 42
13 1 14 962 64
13 1 15 934 0
13 1 16 987 8
13 1 17 1024 8
13 1 18 1090 8
13 1 19 1127 8
13 1 20 1082 8
13 1 21 256 8
13 1 22 1104 40
13 2 10 665 102
13 2 14 1068 72
13 2 15 941 44
13 3 9 312 84
13 3 10 409 42
13 3 16 981 120
13 4 9 383 100
13 4 17 1021 120
13 5 9 373 100
13 5 18 1061 120
13 6 9 326 100
13 6 19 1094 112
13 7 9 112 108
13 7 19 1180 104
13 8 10 283 114
13 8 20 1236 112
13 9 10 196 96
13 9 20 1431 96
13 10 10 79 96
13 10 20 1423 104
13 11 10 21 96
13 11 21 1409 112
13 12 10 77 96
13 12 21 1253 96
13 13 10 37 96
13 13 21 1410 104
13 14 10 70 106
13 14 22 1261 112
13 15 11 134 112
13 15 22 1310 96
13 16 11 38 96
13 16 22 1355 96
13 17 11 353 104
13 17 22 1422 98
13 18 12 190 112
13 18 22 1598 106
13 19 12 328 96
13 19 21 1596 116
13 20 12 289 106
13 20 21 542 102
13 21 13 529 122
13 21 21 1131 102
13 22 14 432 120
13 22 21 1449 110
13 23 15 247 90
13 23 16 316 60
13 23 20 1230 118
13 24 17 159 118
13 24 20 1462 102
13 25 17 49 98
13 25 20 1399 102
13 26 17 93 98
13 26 20 1298 78
13 26 21 1557 50
13 27 17 136 100
13 27 21 1504 98
13 28 17 282 100
13 28 21 1450 98
13 29 17 301 100
13 29 20 1134 86
13 29 21 1238 42
13 30 17 331 74
13 30 18 152 28
13 30 19 179 30
13 30 20 1023 46
14 0 2 994 80
14 0 3 892 16
14 0 4 835 16
14 0 5 805 16
14 0 6 782 16
14 0 7 750 16
14 0 8 718 16
14 0 9 693 16
14 0 10 676 24
14 0 11 657 24
14 0 12 642 24
14 0 13 634 24
14 0 14 627 16
14 0 15 629 16
14 0 16 638 16
14 0 17 654 16
14 0 18 666 16
14 0 19 695 16
14 0 20 727 16
14 0 21 764 16
14 0 22 806 16
14 0 23 845 16
14 0 24 885 16
14 0 25 911 24
14 0 26 965 24
14 0 27 1067 56
14 1 2 1266 72
14 1 3 1317 8
14 1 4 1239 8
14 1 5 1275 8
14 1 6 1206 8
14 1 7 1154 8
14 1 8 1114 2
14 1 9 851 34
14 1 14 871 64
14 1 15 860 0
14 1 16 899 8
14 1 17 954 8
14 1 18 998 8
14 1 19 1049 8
14 1 20 293 8
14 1 21 255 8
14 1 22 983 8
14 1 23 982 12
14 1 24 1078 44
14 2 8 10 78
14 2 9 168 38
14 2 14 682 72
14 2 15 768 40
14 3 9 266 98
14 3 16 832 120
14 4 9 297 98
14 4 17 876 88
14 4 18 1009 54
14 5 9 211 96
14 5 18 1095 104
14 6 9 302 96
14 6 19 1144 112
14 7 9 173 96
14 7 19 1190 104
14 8 9 117 110
14 8 20 1254 114
14 9 10 143 112
14 9 20 1411 96
14 10 10 101 96
14 10 20 1331 104
14 11 10 50 96
14 11 21 1441 114
14 12 10 36 96
14 12 21 1344 98
14 13 10 43 106
14 13 21 1283 104
14 14 11 117 116
14 14 22 1156 114
14 15 11 83 96
14 15 22 1169 98
14 16 11 30 98
14 16 22 1157 106
14 17 11 115 106
14 17 21 1158 116
14 18 12 235 112
14 18 21 480 100
14 19 12 388 106
14 19 21 471 106
14 20 13 400 126
14 20 20 1448 116
14 21 14 261 116
14 21 20 1433 102
14 22 14 171 74
14 22 15 249 62
14 22 19 735 86
14 22 20 1345 46
14 23 16 214 90
14 23 17 140 30
14 23 18 150 22
14 23 19 198 38
14 24 18 202 70
14 24 19 248 38
14 25 18 63 70
14 25 19 126 38
14 26 18 100 70
14 26 19 526 38
14 27 17 177 82
14 27 18 195 6
14 27 19 114 6
14 27 20 1112 54
14 28 17 122 66
14 28 18 153 6
14 28 19 222 6
14 28 20 1002 46
14 29 17 290 74
14 29 18 68 6
14 29 19 71 46
14 30 18 234 106
15 0 2 922 82
15 0 3 861 16
15 0 4 805 16
15 0 5 790 16
15 0 6 756 16
15 0 7 720 16
15 0 8 692 24
15 0 9 663 24
15 0 10 651 24
15 0 11 643 24
15 0 12 621 24
15 0 13 615 24
15 0 14 609 16
15 0 15 609 16
15 0 16 616 16
15 0 17 627 16
15 0 18 638 16
15 0 19 660 16
15 0 20 704 16
15 0 21 741 16
15 0 22 786 16
15 0 23 828 16
15 0 24 867 16
15 0 25 908 24
15 0 26 964 24
15 0 27 989 24
15 0 28 1075 60
15 1 2 1232 74
15 1 3 1287 8
15 1 4 1286 8
15 1 5 1334 8
15 1 6 1115 8
15 1 7 56 34
15 1 14 795 64
15 1 15 848 0
15 1 16 817 8
15 1 17 818 10
15 1 18 361 10
15 1 19 89 10
15 1 20 199 8
15 1 21 131 8
15 1 22 280 8
15 1 23 61 8
15 1 24 1030 40
15 2 7 24 108
15 2 14 647 74
15 2 15 648 42
15 3 8 521 116
15 3 16 632 122
15 4 8 240 110
15 4 17 716 122
15 5 9 192 112
15 5 18 985 120
15 6 9 144 96
15 6 19 1167 112
15 7 9 69 106
15 7 19 1189 96
15 8 10 35 116
15 8 19 1312 108
15 9 10 64 96
15 9 20 1297 114
15 10 10 12 98
15 10 20 1397 96
15 11 10 48 98
15 11 20 869 100
15 12 10 47 106
15 12 20 1381 108
15 13 11 13 116
15 13 21 1413 114
15 14 11 36 98
15 14 21 919 102
15 14 25 631 124
15 15 11 14 106
15 15 21 891 100
15 15 24 342 124
15 16 12 98 116
15 16 21 878 100
15 17 12 85 102
15 17 21 340 98
15 18 12 260 106
15 18 20 933 86
15 18 21 337 42
15 19 13 121 126
15 19 20 1434 102
15 20 14 152 118
15 20 19 365 86
15 20 20 1124 42
15 21 14 62 74
15 21 15 68 30
15 21 16 99 22
15 21 17 121 22
15 21 18 213 22
15 21 19 243 46
15 22 16 95 78
15 22 17 19 14
15 22 18 71 46
16 0 3 725 80
16 0 4 761 16
16 0 5 755 16
16 0 6 717 16
16 0 7 694 24
16 0 8 652 24
16 0 9 628 24
16 0 10 622 24
16 0 11 615 24
16 0 12 600 24
16 0 13 590 24
16 0 14 586 16
16 0 15 587 16
16 0 16 595 16
16 0 17 598 24
16 0 18 607 24
16 0 19 630 24
16 0 20 670 16
16 0 21 711 16
16 0 22 776 16
16 0 23 813 16
16 0 24 866 16
16 0 25 905 16
16 0 26 964 24
16 0 27 963 24
16 0 28 1063 56
16 1 3 1288 72
16 1 4 1234 8
16 1 5 1247 8
16 1 6 1246 40
16 1 14 943 72
16 1 15 1085 8
16 1 16 757 32
16 1 20 154 72
16 1 21 211 8
16 1 22 329 8
16 1 23 1041 8
16 1 24 1233 8
16 1 25 1209 46
16 2 7 254 112
16 2 16 344 76
16 2 17 318 22
16 2 18 221 28
16 2 19 211 60
16 3 7 87 78
16 3 8 788 56
16 3 17 870 108
16 4 9 138 116
16 4 18 435 116
16 5 9 78 98
16 5 18 959 104
16 6 9 12 106
16 6 19 1174 114
16 7 10 45 118
16 7 19 1330 98
16 8 10 43 98
16 8 19 1168 98
16 9 10 7 106
16 9 19 1314 108
16 10 11 4 116
16 10 20 1412 114
16 10 25 602 116
16 11 11 23 102
16 11 20 442 98
16 11 25 569 68
16 11 26 646 54
16 12 11 23 102
16 12 20 555 98
16 12 24 386 84
16 12 25 544 4
16 12 26 466 38
16 13 11 48 74
16 13 12 27 54
16 13 20 488 102
16 13 24 623 68
16 13 25 588 6
16 13 26 328 46
16 14 12 18 102
16 14 20 350 108
16 14 23 309 84
16 14 24 561 4
16 14 25 286 42
16 15 12 74 70
16 15 13 128 54
16 15 21 210 112
16 15 23 585 68
16 15 24 315 34
16 16 12 46 74
16 16 13 16 38
16 16 21 108 72
16 16 22 26 20
16 16 23 8 4
16 16 24 249 46
16 17 13 237 70
16 17 14 103 54
16 17 19 216 84
16 17 20 94 60
16 17 22 402 78
16 17 23 368 46
16 18 13 52 78
16 18 14 68 38
16 18 19 1159 102
16 19 14 11 78
16 19 15 72 54
16 19 18 296 86
16 19 19 360 46
16 20 15 97 78
16 20 16 67 30
16 20 17 96 30
16 20 18 75 46
17 0 3 656 80
17 0 4 736 16
17 0 5 738 16
17 0 6 697 16
17 0 7 664 24
17 0 8 633 24
17 0 9 614 24
17 0 10 605 16
17 0 11 594 16
17 0 12 589 16
17 0 13 573 16
17 0 14 568 16
17 0 15 565 16
17 0 16 571 16
17 0 17 574 16
17 0 18 590 16
17 0 19 609 16
17 0 20 650 16
17 0 21 694 16
17 0 22 766 16
17 0 23 814 16
17 0 24 866 16
17 0 25 904 24
17 0 26 947 24
17 0 27 975 24
17 0 28 1064 56
17 1 3 1217 72
17 1 4 1276 8
17 1 5 1243 8
17 1 6 1140 40
17 1 10 671 76
17 1 11 508 4
17 1 12 639 4
17 1 13 668 4
17 1 14 808 0
17 1 15 809 0
17 1 16 541 0
17 1 17 449 12
17 1 18 428 4
17 1 19 405 4
17 1 20 271 8
17 1 21 173 8
17 1 22 493 8
17 1 23 262 8
17 1 24 1305 40
17 2 7 6 90
17 2 8 31 54
17 2 11 680 70
17 2 12 815 6
17 2 13 984 6
17 2 14 859 6
17 2 15 533 6
17 2 16 204 34
17 2 18 233 66
17 2 19 238 42
17 3 8 109 74
17 3 9 20 22
17 3 10 183 22
17 3 11 233 6
17 3 12 208 6
17 3 13 206 6
17 3 14 187 6
17 3 15 57 6
17 3 16 343 6
17 3 17 1034 18
17 3 18 986 38
17 4 9 155 74
17 4 10 191 6
17 4 11 29 6
17 4 12 440 6
17 4 13 473 6
17 4 14 281 6
17 4 15 424 6
17 4 16 1073 6
17 4 17 1099 6
17 4 18 1226 34
17 5 10 174 70
17 5 11 305 6
17 5 12 156 6
17 5 13 465 6
17 5 14 483 6
17 5 15 674 14
17 5 16 1129 14
17 5 17 1044 6
17 5 18 613 34
17 6 10 46 78
17 6 11 33 6
17 6 12 23 6
17 6 13 378 6
17 6 14 304 38
17 6 17 450 78
17 6 18 1183 38
17 7 11 3 70
17 7 12 148 6
17 7 13 45 6
17 7 14 194 38
17 7 18 1315 102
17 8 11 41 70
17 8 12 162 6
17 8 13 22 6
17 8 14 175 38
17 8 18 1119 102
17 9 11 47 70
17 9 12 65 6
17 9 13 84 6
17 9 14 83 38
17 9 18 877 70
17 9 19 1173 50
17 9 25 338 118
17 10 11 38 74
17 10 12 36 6
17 10 13 125 6
17 10 14 66 38
17 10 18 303 78
17 10 19 532 38
17 10 24 534 86
17 10 25 161 34
17 11 12 165 70
17 11 13 82 6
17 11 14 230 6
17 11 15 636 54
17 11 19 377 102
17 11 24 1123 70
17 11 25 158 34
17 12 12 15 78
17 12 13 164 6
17 12 14 120 6
17 12 15 339 6
17 12 16 1368 54
17 12 19 500 102
17 12 23 1010 86
17 12 24 102 2
17 12 25 133 42
17 13 13 135 70
17 13 14 201 6
17 13 15 847 6
17 13 16 1262 6
17 13 17 223 22
17 13 18 259 30
17 13 19 445 44
17 13 22 1098 84
17 13 23 644 6
17 13 24 98 34
17 14 13 180 78
17 14 14 184 6
17 14 15 224 6
17 14 16 1311 6
17 14 17 310 38
17 14 20 387 88
17 14 21 506 20
17 14 22 186 4
17 14 23 51 2
17 14 24 80 42
17 15 14 44 70
17 15 15 288 6
17 15 16 292 6
17 15 17 1426 38
17 15 21 539 64
17 15 22 40 6
17 15 23 125 34
17 16 14 42 78
17 16 15 118 6
17 16 16 298 6
17 16 17 134 38
17 16 21 121 74
17 16 22 73 10
17 16 23 182 42
17 17 15 81 70
17 17 16 97 6
17 17 17 197 6
17 17 18 178 22
17 17 19 284 26
17 17 20 221 58
17 18 15 291 78
17 18 16 176 6
17 18 17 250 6
17 18 18 272 46
17 19 16 120 78
17 19 17 197 46
18 0 3 777 82
18 0 4 770 16
18 0 5 737 16
18 0 6 698 16
18 0 7 649 16
18 0 8 618 16
18 0 9 599 16
18 0 10 582 16
18 0 11 567 16
18 0 12 560 16
18 0 13 551 16
18 0 14 548 16
18 0 15 537 16
18 0 16 540 16
18 0 17 545 16
18 0 18 553 16
18 0 19 572 16
18 0 20 601 16
18 0 21 658 16
18 0 22 778 16
18 0 23 834 16
18 0 24 888 16
18 0 25 915 16
18 0 26 991 24
18 0 27 1011 24
18 0 28 1126 58
18 1 3 1356 72
18 1 4 1219 8
18 1 5 1197 8
18 1 6 1233 8
18 1 7 1121 12
18 1 8 999 12
18 1 9 897 4
18 1 10 917 0
18 1 11 912 8
18 1 12 907 8
18 1 13 955 8
18 1 14 957 8
18 1 15 928 8
18 1 16 1029 8
18 1 17 1077 0
18 1 18 1084 8
18 1 19 1103 8
18 1 20 1108 8
18 1 21 1117 8
18 1 22 1218 8
18 1 23 1370 8
18 1 24 1363 8
18 1 25 1362 44
18 2 9 34 78
18 2 10 458 46
18 2 17 323 110
18 6 15 356 86
18 6 16 1213 54
18 7 15 277 70
18 7 16 1145 6
18 7 17 295 54
18 8 15 150 70
18 8 16 1191 6
18 8 17 255 38
18 9 15 245 70
18 9 16 1130 6
18 9 17 116 38
18 10 15 327 78
18 10 16 1256 6
18 10 17 88 38
18 11 16 1185 78
18 11 17 170 6
18 11 18 214 54
18 12 17 160 78
18 12 18 300 46
18 13 19 496 82
18 13 20 1216 20
18 13 21 696 22
18 13 22 515 50
18 14 18 60 86
18 14 19 39 6
18 14 20 5 2
18 14 21 17 2
18 14 22 54 42
18 15 18 53 70
18 15 19 39 6
18 15 20 86 6
18 15 21 28 42
18 16 18 251 78
18 16 19 48 14
18 16 20 106 46
19 0 4 875 80
19 0 5 749 16
19 0 6 684 16
19 0 7 626 16
19 0 8 606 16
19 0 9 573 16
19 0 10 557 16
19 0 11 546 16
19 0 12 530 16
19 0 13 527 16
19 0 14 502 16
19 0 15 492 16
19 0 16 491 16
19 0 17 491 16
19 0 18 503 16
19 0 19 517 16
19 0 20 566 16
19 0 21 637 16
19 0 22 775 16
19 0 23 887 16
19 0 24 939 16
19 0 25 980 16
19 0 26 1006 26
19 0 27 1091 58
19 1 3 1177 90
19 1 4 1316 8
19 1 5 1247 8
19 1 6 1277 8
19 1 7 1273 8
19 1 8 1264 8
19 1 9 1289 8
19 1 10 1278 8
19 1 11 1171 8
19 1 12 1107 8
19 1 13 1049 8
19 1 14 1083 8
19 1 15 1200 8
19 1 16 1211 8
19 1 17 1326 8
19 1 18 1303 8
19 1 19 1325 8
19 1 20 1349 8
19 1 21 1307 8
19 1 22 1337 8
19 1 23 1357 8
19 1 24 1319 10
19 1 25 1346 42
19 13 20 422 122
20 0 4 857 80
20 0 5 729 16
20 0 6 659 16
20 0 7 608 16
20 0 8 578 16
20 0 9 547 16
20 0 10 536 16
20 0 11 524 16
20 0 12 498 16
20 0 13 487 16
20 0 14 476 16
20 0 15 456 16
20 0 16 436 16
20 0 17 416 16
20 0 18 417 16
20 0 19 430 16
20 0 20 412 16
20 0 21 596 16
20 0 22 890 18
20 0 23 971 18
20 0 24 1004 26
20 0 25 1048 58
20 1 4 1176 72
20 1 5 1245 8
20 1 6 1284 8
20 1 7 1301 8
20 1 8 1268 8
20 1 9 1333 8
20 1 10 1303 8
20 1 11 1336 8
20 1 12 1451 8
20 1 13 1471 8
20 1 14 1498 8
20 1 15 1394 8
20 1 16 1308 8
20 1 17 1364 8
20 1 18 1350 8
20 1 19 1339 8
20 1 20 1359 8
20 1 21 1323 10
20 1 22 1306 10
20 1 23 1204 42
21 0 4 726 82
21 0 5 731 16
21 0 6 635 16
21 0 7 579 16
21 0 8 535 16
21 0 9 516 16
21 0 10 490 16
21 0 11 479 16
21 0 12 463 16
21 0 13 455 16
21 0 14 448 16
21 0 15 363 16
21 0 16 320 16
21 0 17 226 16
21 0 18 185 16
21 0 19 241 18
21 0 20 107 18
21 0 21 881 58
21 1 4 1274 72
21 1 5 1265 8
21 1 6 1300 8
21 1 7 1279 8
21 1 8 1304 8
21 1 9 1335 8
21 1 10 1446 8
21 1 11 1497 8
21 1 12 1494 8
21 1 13 1584 8
21 1 14 1524 8
21 1 15 1525 8
21 1 16 1455 8
21 1 17 1545 8
21 1 18 1382 10
21 1 19 1139 10
21 1 20 1125 42
22 0 5 800 80
22 0 6 590 16
22 0 7 554 16
22 0 8 490 16
22 0 9 475 16
22 0 10 454 16
22 0 11 433 16
22 0 12 404 16
22 0 13 394 16
22 0 14 376 16
22 0 15 264 16
22 0 16 225 18
22 0 17 76 18
22 0 18 1 58
22 1 4 1186 90
22 1 5 1205 8
22 1 6 1302 8
22 1 7 1318 8
22 1 8 1384 8
22 1 9 1464 8
22 1 10 1509 8
22 1 11 1553 8
22 1 12 1576 8
22 1 13 1581 8
22 1 14 1601 8
22 1 15 1578 10
22 1 16 1285 10
22 1 17 1141 42
23 0 5 641 80
23 0 6 564 16
23 0 7 489 16
23 0 8 379 16
23 0 9 306 16
23 0 10 294 16
23 0 11 414 16
23 0 12 141 18
23 0 13 403 18
23 0 14 355 18
23 0 15 276 58
23 1 5 1161 72
23 1 6 1374 8
23 1 7 1436 8
23 1 8 1481 8
23 1 9 1508 8
23 1 10 1544 8
23 1 11 1554 8
23 1 12 1593 10
23 1 13 1383 10
23 1 14 1207 42
24 0 5 556 82
24 0 6 523 16
24 0 7 434 16
24 0 8 55 18
24 0 9 2 18
24 0 10 0 18
24 0 11 375 50
24 1 5 1113 72
24 1 6 1445 8
24 1 7 1496 8
24 1 8 1548 8
24 1 9 1579 10
24 1 10 1427 10
24 1 11 1195 42
25 0 6 655 82
25 0 7 203 50
25 1 5 898 90
25 1 6 1454 10
25 1 7 1352 10
25 1 8 1428 58
